Workbook

Sheet Jelenlét
A1: Név: | B1: András Papp | C1: Anna Sengler | D1: Annamária Földváry | E1: Flóra & Boti | F1: Csanád Laczkó | G1: Csenge Domokos | H1: Detti Szabó | I1: Dóri Békási | J1: Gergely Márki | K1: Kilyénfalvi Júlia | L1: Kristóf Szelényi | M1: Laura Piski | N1: Léna Piski | O1: Linda Antal | P1: Máté Lajer | Q1: Nóri Sásdi | R1: Laci Márki | S1: Domokos Kadosa | T1: Áron Szabó | U1: Máté Plank | V1: Lea Plank | W1: Plusz emberek száma
A2: 45594 | B2: Nem jövök :( | C2: Nem jövök :( | D2: Jövök :) | E2: Jövök :) | F2: Jövök :) | G2: Nem jövök :( | I2: Jövök :) | J2: Jövök :) | K2: Nem jövök :( | L2: Jövök :) | M2: Jövök :) | N2: Jövök :) | O2: Jövök :) | P2: Nem jövök :( | U2: Nem jövök :( | Y2: =COUNTIF(B2:R2,"Jövök :)") -> 9
A3: 45601 | B3: Nem jövök :( | C3: Nem jövök :( | D3: Nem jövök :( | E3: Nem jövök :( | F3: Jövök :) | G3: Jövök :) | H3: Jövök :) | I3: Jövök :) | J3: Jövök :) | K3: Nem jövök :( | L3: Nem jövök :( | M3: Jövök :) | N3: Nem jövök :( | O3: Nem jövök :( | P3: Nem jövök :( | U3: Nem jövök :( | Y3: =COUNTIF(B3:U3,"Jövök :)") -> 6 | Z3: =(1.55*14000)/(Y3+W3) -> 3616.6667
A4: 45608 | B4: Jövök :) | C4: Nem jövök :( | D4: Jövök :) | E4: Nem jövök :( | F4: Jövök :) | G4: Jövök :) | H4: Jövök :) | I4: Jövök :) | J4: Jövök :) | K4: Nem jövök :( | L4: Jövök :) | M4: Nem jövök :( | N4: Nem jövök :( | O4: Nem jövök :( | P4: Nem jövök :( | U4: Nem jövök :( | Y4: =COUNTIF(B4:U4,"Jövök :)") -> 8 | Z4: =(1.55*14000)/(Y4+W4) -> 2712.5
A5: 45615 | B5: Jövök :) | C5: Nem jövök :( | D5: Jövök :) | E5: Jövök :) | F5: Jövök :) | G5: Jövök :) | H5: Jövök :) | I5: Jövök :) | J5: Jövök :) | K5: Jövök :) | L5: Nem jövök :( | M5: Nem jövök :( | N5: Nem jövök :( | O5: Nem jövök :( | P5: Nem jövök :( | Q5: Jövök :) | U5: Nem jövök :( | Y5: =COUNTIF(B5:U5,"Jövök :)") -> 10 | Z5: =(1.55*14000)/(Y5+W5) -> 2170
A6: 45622 | B6: Jövök :) | C6: Nem jövök :( | D6: Nem jövök :( | E6: Nem jövök :( | F6: Jövök :) | G6: Jövök :) | H6: Jövök :) | I6: Jövök :) | J6: Jövök :) | K6: Nem jövök :( | L6: Jövök :) | M6: Nem jövök :( | N6: Nem jövök :( | O6: Nem jövök :( | P6: Jövök :) | Q6: Nem jövök :( | R6: Jövök :) | S6: Nem jövök :( | U6: Nem jövök :( | W6: 0 | Y6: =COUNTIF(B6:U6,"Jövök :)") -> 9 | Z6: =(1.55*14000)/(Y6+W6) -> 2411.1111
A7: 45629 | B7: Nem jövök :( | C7: Nem jövök :( | D7: Jövök :) | E7: Nem jövök :( | F7: Jövök :) | G7: Jövök :) | H7: Nem jövök :( | I7: Jövök :) | J7: Jövök :) | K7: Nem jövök :( | L7: Nem jövök :( | M7: Nem jövök :( | N7: Nem jövök :( | O7: Jövök :) | P7: Nem jövök :( | Q7: Nem jövök :( | R7: Jövök :) | S7: Nem jövök :( | U7: Nem jövök :( | W7: 1 | Y7: =COUNTIF(B7:U7,"Jövök :)") -> 7 | Z7: =(1.55*14000)/(Y7+W7) -> 2712.5
A8: 45636 | B8: Jövök :) | C8: Jövök :) | D8: Jövök :) | E8: Jövök :) | F8: Jövök :) | G8: Jövök :) | H8: Nem jövök :( | I8: Nem jövök :( | J8: Jövök :) | K8: Nem jövök :( | L8: Jövök :) | M8: Nem jövök :( | N8: Nem jövök :( | O8: Nem jövök :( | P8: Nem jövök :( | Q8: Nem jövök :( | R8: Jövök :) | S8: Jövök :) | T8: Jövök :) | U8: Nem jövök :( | W8: 2 | Y8: =COUNTIF(B8:U8,"Jövök :)") -> 11 | Z8: =(1.55*14000)/(Y8+W8) -> 1669.2308
A9: 45643 | B9: Nem jövök :( | C9: Nem jövök :( | D9: Jövök :) | E9: Jövök :) | F9: Jövök :) | G9: Jövök :) | H9: Jövök :) | I9: Nem jövök :( | J9: Jövök :) | K9: Jövök :) | L9: Nem jövök :( | M9: Nem jövök :( | N9: Nem jövök :( | O9: Jövök :) | Q9: Nem jövök :( | R9: Jövök :) | S9: Nem jövök :( | T9: Jövök :) | U9: Jövök :) | Y9: =COUNTIF(B9:U9,"Jövök :)") -> 11 | Z9: =(2.1*15000)/(Y9+W9) -> 2863.6364
A10: 45664 | B10: Nem jövök :( | C10: Nem jövök :( | D10: Jövök :) | E10: Nem jövök :( | F10: Nem jövök :( | G10: Jövök :) | H10: Jövök :) | I10: Jövök :) | J10: Jövök :) | K10: Nem jövök :( | M10: Nem jövök :( | N10: Nem jövök :( | Q10: Nem jövök :( | R10: Jövök :) | S10: Nem jövök :( | T10: Jövök :) | U10: Jövök :) | Y10: =COUNTIF(B10:U10,"Jövök :)") -> 8 | Z10: =(1.51*14000)/(Y10+W10) -> 2642.5
A11: 45671 | B11: Nem jövök :( | C11: Jövök :) | D11: Jövök :) | E11: Jövök :) | F11: Nem jövök :( | G11: Jövök :) | H11: Nem jövök :( | I11: Jövök :) | J11: Jövök :) | K11: Nem jövök :( | M11: Nem jövök :( | N11: Nem jövök :( | Q11: Nem jövök :( | R11: Jövök :) | S11: Jövök :) | T11: Jövök :) | U11: Jövök :) | Y11: =COUNTIF(B11:U11,"Jövök :)") -> 10 | Z11: =(1.51*14000)/(Y11+W11) -> 2114
A12: 45678 | B12: Nem jövök :( | C12: Jövök :) | D12: Nem jövök :( | E12: Jövök :) | F12: Nem jövök :( | G12: Jövök :) | H12: Nem jövök :( | I12: Jövök :) | J12: Jövök :) | K12: Nem jövök :( | M12: Jövök :) | N12: Nem jövök :( | Q12: Nem jövök :( | R12: Jövök :) | S12: Jövök :) | T12: Jövök :) | U12: Jövök :) | W12: 1 | Y12: =COUNTIF(B12:U12,"Jövök :)") -> 10 | Z12: =(1.51*14000)/(Y12+W12) -> 1921.8182
A13: 45685 | B13: Nem jövök :( | C13: Jövök :) | D13: Nem jövök :( | E13: Nem jövök :( | F13: Nem jövök :( | G13: Jövök :) | H13: Jövök :) | I13: Jövök :) | J13: Nem jövök :( | K13: Nem jövök :( | M13: Jövök :) | N13: Nem jövök :( | Q13: Jövök :) | R13: Nem jövök :( | S13: Jövök :) | T13: Jövök :) | U13: Nem jövök :( | W13: 2 | Y13: =COUNTIF(B13:U13,"Jövök :)") -> 8 | Z13: =(1.51*14000)/(Y13+W13) -> 2114
A14: 45692 | B14: Jövök :) | C14: Nem jövök :( | D14: Nem jövök :( | E14: Nem jövök :( | F14: Nem jövök :( | G14: Jövök :) | H14: Jövök :) | I14: Jövök :) | J14: Nem jövök :( | K14: Nem jövök :( | M14: Nem jövök :( | N14: Nem jövök :( | Q14: Jövök :) | R14: Jövök :) | S14: Jövök :) | T14: Nem jövök :( | U14: Nem jövök :( | W14: 4 | Y14: =COUNTIF(B14:U14,"Jövök :)") -> 7 | Z14: =(1.78*14000)/(Y14+W14) -> 2265.4545
A15: 45699 | B15: Jövök :) | C15: Jövök :) | D15: Jövök :) | E15: Nem jövök :( | F15: Jövök :) | G15: Jövök :) | H15: Jövök :) | I15: Jövök :) | J15: Jövök :) | K15: Nem jövök :( | M15: Nem jövök :( | N15: Nem jövök :( | O15: Nem jövök :( | Q15: Jövök :) | R15: Jövök :) | S15: Jövök :) | T15: Jövök :) | U15: Nem jövök :( | W15: 2 | Y15: =COUNTIF(B15:U15,"Jövök :)") -> 12 | Z15: =(1.78*14000)/(Y15+W15) -> 1780
A16: 45706 | B16: Nem jövök :( | C16: Jövök :) | D16: Jövök :) | E16: Nem jövök :( | F16: Jövök :) | G16: Jövök :) | H16: Jövök :) | I16: Jövök :) | J16: Jövök :) | M16: Nem jövök :( | Q16: Jövök :) | R16: Jövök :) | S16: Jövök :) | T16: Nem jövök :( | U16: Jövök :) | W16: 1 | Y16: =COUNTIF(B16:U16,"Jövök :)") -> 11 | Z16: =(1.78*14000)/(Y16+W16) -> 2076.6667
A17: 45713 | B17: Nem jövök :( | C17: Jövök :) | D17: Jövök :) | E17: Nem jövök :( | F17: Jövök :) | G17: Jövök :) | H17: Jövök :) | I17: Jövök :) | J17: Jövök :) | Q17: Nem jövök :( | R17: Jövök :) | S17: Nem jövök :( | T17: Jövök :) | U17: Jövök :) | Y17: =COUNTIF(B17:U17,"Jövök :)") -> 10 | Z17: =(1.78*14000)/(Y17+W17) -> 2492
A18: 45720 | B18: 1 | C18: 0 | D18: 0 | E18: 0 | F18: 1 | G18: 2 | H18: 1 | I18: 1 | J18: 1 | K18: 0 | L18: 0 | M18: 0 | N18: 0 | O18: 0 | P18: 0 | Q18: 1 | R18: 2 | S18: 1 | T18: 0 | U18: 1 | W18: Viki | Y18: =SUM(B18:U18) -> 12 | Z18: =(1.6875*14000)/(Y18) -> 1968.75
A19: 45727 | B19: 0 | C19: 0 | D19: 1 | E19: 0 | F19: 1 | G19: 1 | H19: 1 | I19: 1 | J19: 1 | K19: 0 | L19: 0 | M19: 0 | N19: 0 | O19: 0 | P19: 0 | Q19: 1 | R19: 0 | S19: 1 | T19: 0 | U19: 1 | Y19: =SUM(B19:U19) -> 9 | Z19: =(1.6875*14000)/(Y19) -> 2625
A20: 45734 | B20: 0 | C20: 1 | D20: 1 | E20: 1 | F20: 1 | G20: 2 | H20: 1 | I20: 1 | J20: 1 | K20: 0 | L20: 0 | M20: 0 | N20: 0 | O20: 0 | P20: 0 | Q20: 1 | R20: 1 | S20: 1 | T20: 0 | U20: 1 | Y20: =SUM(B20:U20) -> 13 | Z20: =(1.6875*14000)/(Y20) -> 1817.3077
A21: 45741 | B21: 0 | C21: 1 | D21: 1 | E21: 0 | F21: 1 | G21: 1 | H21: 1 | I21: 1 | J21: 1 | K21: 0 | L21: 0 | M21: 0 | N21: 0 | O21: 0 | P21: 0 | Q21: 1 | R21: 2 | S21: 1 | T21: 1 | U21: 1 | Y21: =SUM(B21:U21) -> 13 | Z21: =(1.6875*14000)/(Y21) -> 1817.3077
A22: 45748 | B22: 0 | C22: 1 | D22: 0 | E22: 0 | F22: 1 | G22: 3 | H22: 1 | I22: 1 | J22: 0 | K22: 0 | L22: 0 | M22: 0 | N22: 0 | O22: 0 | P22: 0 | Q22: 1 | R22: 0 | S22: 1 | T22: 0 | U22: 1 | W22: Luca Lilla | Y22: =SUM(B22:U22) -> 10 | Z22: =(1.604*14000)/(Y22) -> 2245.6
A23: 45755 | B23: 0 | C23: 0 | D23: 1 | E23: 0 | F23: 0 | G23: 2 | H23: 1 | I23: 1 | J23: 1 | K23: 0 | L23: 0 | M23: 0 | N23: 0 | O23: 0 | P23: 0 | Q23: 0 | R23: 3 | S23: 0 | T23: 1 | U23: 1 | W23: Tardos, Balázs, Luca | Y23: =SUM(B23:U23) -> 11 | Z23: =(1.604*14000)/(Y23) -> 2041.4545
A24: 45762 | B24: 0 | C24: 0 | D24: 1 | E24: 2 | F24: 1 | G24: 1 | H24: 1 | I24: 1 | J24: 1 | K24: 0 | L24: 0 | M24: 0 | N24: 0 | O24: 0 | P24: 0 | Q24: 1 | R24: 2 | S24: 0 | T24: 0 | U24: 1 | W24: Sanyi | Y24: =SUM(B24:U24) -> 12 | Z24: =(1.604*14000)/(Y24) -> 1871.3333
A25: 45769 | B25: 0 | C25: 1 | D25: 0 | E25: 0 | F25: 0 | G25: 0 | H25: 1 | I25: 1 | J25: 0 | K25: 0 | L25: 0 | M25: 0 | N25: 0 | O25: 0 | P25: 0 | Q25: 1 | R25: 4 | S25: 1 | T25: 0 | U25: 1 | W25: Biha, Sanyi, Zoli | Y25: =SUM(B25:U25) -> 10 | Z25: =(1.604*14000)/(Y25) -> 2245.6
A26: 45776 | B26: 0 | C26: 0 | D26: 1 | E26: 0 | F26: 1 | G26: 2 | H26: 1 | I26: 1 | J26: 1 | K26: 0 | L26: 1 | M26: 0 | N26: 0 | O26: 0 | P26: 1 | Q26: 1 | R26: 1 | S26: 0 | T26: 1 | U26: 1 | W26: Luca | Y26: =SUM(B26:U26) -> 13 | Z26: =(1.604*14000)/(Y26) -> 1727.3846
A27: 45783 | B27: 0 | C27: 1 | D27: 1 | E27: 0 | F27: 1 | G27: 1 | H27: 1 | I27: 1 | J27: 1 | K27: 0 | L27: 0 | M27: 0 | N27: 0 | O27: 0 | P27: 0 | Q27: 0 | R27: 0 | S27: 0 | T27: 1 | U27: 1 | Y27: =SUM(B27:U27) -> 9 | Z27: =(1.65*14000)/(Y27) -> 2566.6667
A28: 45790 | B28: 0 | C28: 0 | D28: 1 | E28: 0 | F28: 1 | G28: 1 | H28: 0 | I28: 0 | J28: 1 | K28: 0 | L28: 0 | M28: 0 | N28: 0 | O28: 0 | P28: 0 | Q28: 0 | R28: 3 | S28: 1 | T28: 0 | U28: 1 | W28: Sanyi, Mór | Y28: =SUM(B28:U28) -> 9 | Z28: =(1.65*14000)/(Y28) -> 2566.6667
A29: 45797 | B29: 0 | C29: 1 | D29: 0 | E29: 0 | F29: 0 | G29: 1 | H29: 1 | I29: 0 | J29: 0 | K29: 0 | L29: 0 | M29: 0 | N29: 0 | O29: 0 | P29: 0 | Q29: 1 | R29: 5 | S29: 0 | T29: 0 | U29: 0 | W29: Sanyi, Mór, Zoli, Tardos, Barna, Márk | Y29: =SUM(B29:U29) -> 9 | Z29: =(1.65*14000)/(Y29) -> 2566.6667
A30: 45804 | B30: 0 | C30: 1 | D30: 1 | E30: 2 | F30: 1 | G30: 1 | H30: 1 | I30: 1 | J30: 1 | K30: 0 | L30: 0 | M30: 0 | N30: 0 | O30: 0 | P30: 0 | Q30: 1 | R30: 0 | S30: 2 | T30: 1 | U30: 1 | W30: Ábel | Y30: =SUM(B30:U30) -> 14 | Z30: =(1.65*14000)/(Y30) -> 1650
A31: 45811 | B31: 0 | C31: 0 | D31: 0 | E31: 0 | F31: 1 | G31: 1 | H31: 1 | I31: 1 | J31: 1 | K31: 0 | L31: 0 | M31: 0 | N31: 0 | O31: 0 | P31: 0 | Q31: 1 | R31: 3 | S31: 0 | T31: 1 | U31: 1 | W31: Szalmy, Janek, Kemper | Y31: =SUM(B31:V31) -> 11 | Z31: =(1.6975*14000)/(Y31) -> 2160.4545
A32: 45818 | B32: 0 | C32: 1 | D32: 0 | E32: 0 | F32: 1 | G32: 1 | H32: 1 | I32: 1 | J32: 1 | K32: 0 | L32: 0 | M32: 0 | N32: 0 | O32: 0 | P32: 0 | Q32: 1 | R32: 4 | S32: 1 | T32: 0 | U32: 1 | W32: Kemper, Sanyi. Janek | Y32: =SUM(B32:V32) -> 13 | Z32: =(1.6975*14000)/(Y32) -> 1828.0769
A33: 45825 | B33: 0 | C33: 1 | D33: 1 | E33: 0 | F33: 1 | G33: 1 | H33: 1 | I33: 1 | J33: 1 | K33: 0 | L33: 0 | M33: 0 | N33: 0 | O33: 0 | P33: 0 | Q33: 1 | R33: 2 | S33: 1 | T33: 0 | U33: 1 | W33: Szalmi | Y33: =SUM(B33:V33) -> 12 | Z33: =(1.6975*14000)/(Y33) -> 1980.4167
A34: 45832 | B34: 0 | C34: 1 | D34: 1 | E34: 0 | F34: 1 | G34: 1 | H34: 1 | I34: 1 | J34: 1 | K34: 0 | L34: 0 | M34: 0 | N34: 0 | O34: 0 | P34: 0 | Q34: 1 | R34: 1 | S34: 2 | T34: 1 | U34: 1 | V34: 1 | W34: Lea,Ábel | Y34: =SUM(B34:V34) -> 14 | Z34: =(1.6975*14000)/(Y34) -> 1697.5
A35: 45839 | B35: 0 | C35: 1 | D35: 1 | E35: 2 | F35: 1 | G35: 1 | H35: 1 | I35: 1 | J35: 1 | K35: 1 | L35: 0 | M35: 0 | N35: 0 | O35: 0 | P35: 0 | Q35: 1 | R35: 2 | S35: 0 | T35: 0 | U35: 1 | V35: 1 | W35: Lea, Szalmy, kata | Y35: =SUM(B35:V35) -> 15 | Z35: =(1.724*14000)/(Y35) -> 1609.0667
A36: 45846 | B36: 0 | C36: 0 | D36: 1 | E36: 0 | F36: 2 | G36: 2 | H36: 0 | I36: 1 | J36: 2 | K36: 0 | L36: 0 | M36: 0 | N36: 0 | O36: 0 | P36: 0 | Q36: 0 | R36: 3 | S36: 1 | T36: 1 | U36: 1 | V36: 1 | W36: Beten, Ocean, Lea (Mátéhoz írtam), Tarzan, Janek (sorry Laci hozzád írtam), Peti (Gergőhöz írtam xd) | Y36: =SUM(B36:V36) -> 15 | Z36: =(1.724*14000)/(Y36) -> 1609.0667
A37: 45853 | B37: 0 | C37: 1 | D37: 0 | E37: 0 | F37: 2 | G37: 2 | H37: 0 | I37: 0 | J37: 0 | K37: 0 | L37: 0 | M37: 0 | N37: 0 | O37: 0 | P37: 0 | Q37: 1 | R37: 0 | S37: 3 | T37: 1 | U37: 1 | V37: 1 | W37: Beten (Csenge), Ocean (Csanád), Lea (Máté), Szabi, Vendi (Kadi) | Y37: =SUM(B37:V37) -> 12 | Z37: =(1.724*14000)/(Y37) -> 2011.3333
A38: 45860 | B38: 0 | C38: 1 | D38: 1 | E38: 0 | F38: 2 | G38: 0 | H38: 0 | I38: 0 | J38: 1 | K38: 0 | L38: 0 | M38: 0 | N38: 0 | O38: 0 | P38: 0 | Q38: 0 | R38: 6 | S38: 0 | T38: 0 | U38: 1 | W38: Kemper, Sanyi, Szalmy, Ádi, Anna, | Y38: =SUM(B38:V38) -> 12 | Z38: =(1.724*14000)/(Y38) -> 2011.3333
A39: 45867 | B39: 0 | C39: 0 | D39: 3 | E39: 2 | F39: 1 | G39: 1 | H39: 1 | I39: 1 | J39: 1 | K39: 0 | L39: 0 | M39: 0 | N39: 0 | O39: 0 | P39: 0 | Q39: 0 | R39: 0 | S39: 0 | T39: 0 | U39: 1 | V39: 1 | W39: Lea (Máté), Levi, Vera (Anna) | Y39: =SUM(B39:V39) -> 12 | Z39: =(1.724*14000)/(Y39) -> 2011.3333
A40: 45874 | B40: 0 | C40: 0 | D40: 4 | E40: 3 | F40: 1 | G40: 0 | H40: 1 | I40: 0 | J40: 1 | K40: 0 | L40: 0 | M40: 0 | N40: 0 | O40: 0 | P40: 0 | Q40: 1 | R40: 1 | S40: 0 | T40: 1 | U40: 0 | W40: Züri (Flóra) Anna tesói és ismerősei | Y40: =SUM(B40:V40) -> 13 | Z40: =(1.715*14000)/(Y40) -> 1846.9231 | AA40: =Z40*Y40 -> 24010
...

Sheet Számolás
A1: Név: | B1: András Papp | C1: Anna Sengler | D1: Annamária Földváry | E1: Flóra & Boti | F1: Csanád Laczkó | G1: Csenge Domokos | H1: Detti Szabó | I1: Dóri Békási | J1: Gergely Márki | K1: Kijénfalvi Júlia | L1: Kristóf szelényi | M1: Laura Piski | N1: Léna Piski | O1: Linda Antal | P1: Máté Lajer | Q1: Nóri Sásdi | R1: Laci Márki | S1: Kadosa Domokos | T1: Áron Szabó | U1: Máté Plank | V1: Lea Plank | W1: Plusz ember költség
A2: 45594 | B2: =IF('Jelenlét'!B2="Jövök :)",'Jelenlét'!$Z2,"") | C2: =IF('Jelenlét'!C2="Jövök :)",'Jelenlét'!$Z2,"") | D2: =IF('Jelenlét'!D2="Jövök :)",'Jelenlét'!$Z2,"") | E2: =IF('Jelenlét'!E2="Jövök :)",'Jelenlét'!$Z2,"") | F2: =IF('Jelenlét'!F2="Jövök :)",'Jelenlét'!$Z2,"") | G2: =IF('Jelenlét'!G2="Jövök :)",'Jelenlét'!$Z2,"") | H2: =IF('Jelenlét'!H2="Jövök :)",'Jelenlét'!$Z2,"") | I2: =IF('Jelenlét'!I2="Jövök :)",'Jelenlét'!$Z2,"") | ... R2: =IF('Jelenlét'!R2="Jövök :)",'Jelenlét'!$Z2,"") | S2: =IF('Jelenlét'!Y2="Jövök :)",'Jelenlét'!AV2,"") | T2: =IF('Jelenlét'!Z2="Jövök :)",'Jelenlét'!AW2,"") | U2: =IF('Jelenlét'!AA2="Jövök :)",'Jelenlét'!AX2,"") | V2: =IF('Jelenlét'!AB2="Jövök :)",'Jelenlét'!AY2,"")
A3: 45601 | B3: =IF('Jelenlét'!B3="Jövök :)",'Jelenlét'!$AA3,"") | C3: =IF('Jelenlét'!C3="Jövök :)",'Jelenlét'!$AA3,"") | D3: =IF('Jelenlét'!D3="Jövök :)",'Jelenlét'!$AA3,"") | E3: =IF('Jelenlét'!E3="Jövök :)",'Jelenlét'!$AA3,"") | F3: =IF('Jelenlét'!F3="Jövök :)",'Jelenlét'!$AA3,"") | G3: =IF('Jelenlét'!G3="Jövök :)",'Jelenlét'!$AA3,"") | H3: =IF('Jelenlét'!H3="Jövök :)",'Jelenlét'!$AA3,"") | I3: =IF('Jelenlét'!I3="Jövök :)",'Jelenlét'!$AA3,"") | ... R3: =IF('Jelenlét'!R3="Jövök :)",'Jelenlét'!$AA3,"") | S3: =IF('Jelenlét'!Y3="Jövök :)",'Jelenlét'!AV3,"") | T3: =IF('Jelenlét'!AA3="Jövök :)",'Jelenlét'!AW3,"") | V3: =IF('Jelenlét'!AB3="Jövök :)",'Jelenlét'!AY3,"")
A4: 45608 | B4: =IF('Jelenlét'!B4="Jövök :)",'Jelenlét'!$Z4,"") -> 2712.5 | C4: =IF('Jelenlét'!C4="Jövök :)",'Jelenlét'!$Z4,"") | D4: =IF('Jelenlét'!D4="Jövök :)",'Jelenlét'!$Z4,"") -> 2712.5 | E4: =IF('Jelenlét'!E4="Jövök :)",'Jelenlét'!$Z4,"") | F4: =IF('Jelenlét'!F4="Jövök :)",'Jelenlét'!$Z4,"") -> 2712.5 | G4: =IF('Jelenlét'!G4="Jövök :)",'Jelenlét'!$Z4,"") -> 2712.5 | H4: =IF('Jelenlét'!H4="Jövök :)",'Jelenlét'!$Z4,"") -> 2712.5 | I4: =IF('Jelenlét'!I4="Jövök :)",'Jelenlét'!$Z4,"") -> 2712.5 | ... R4: =IF('Jelenlét'!R4="Jövök :)",'Jelenlét'!$Z4,"") | S4: =IF('Jelenlét'!Y4="Jövök :)",'Jelenlét'!AV4,"") | T4: =IF('Jelenlét'!Z4="Jövök :)",'Jelenlét'!AW4,"") | U4: =IF('Jelenlét'!AA4="Jövök :)",'Jelenlét'!AX4,"") | V4: =IF('Jelenlét'!AB4="Jövök :)",'Jelenlét'!AY4,"")
A5: 45615 | B5: =IF('Jelenlét'!B5="Jövök :)",'Jelenlét'!$Z5,"") -> 2170 | C5: =IF('Jelenlét'!C5="Jövök :)",'Jelenlét'!$Z5,"") | D5: =IF('Jelenlét'!D5="Jövök :)",'Jelenlét'!$Z5,"") -> 2170 | E5: =IF('Jelenlét'!E5="Jövök :)",'Jelenlét'!$Z5,"") -> 2170 | F5: =IF('Jelenlét'!F5="Jövök :)",'Jelenlét'!$Z5,"") -> 2170 | G5: =IF('Jelenlét'!G5="Jövök :)",'Jelenlét'!$Z5,"") -> 2170 | H5: =IF('Jelenlét'!H5="Jövök :)",'Jelenlét'!$Z5,"") -> 2170 | I5: =IF('Jelenlét'!I5="Jövök :)",'Jelenlét'!$Z5,"") -> 2170 | ... R5: =IF('Jelenlét'!R5="Jövök :)",'Jelenlét'!$Z5,"") | S5: =IF('Jelenlét'!Y5="Jövök :)",'Jelenlét'!AV5,"") | T5: =IF('Jelenlét'!Z5="Jövök :)",'Jelenlét'!AW5,"") | U5: =IF('Jelenlét'!AA5="Jövök :)",'Jelenlét'!AX5,"") | V5: =IF('Jelenlét'!AB5="Jövök :)",'Jelenlét'!AY5,"")
A6: 45622 | B6: =IF('Jelenlét'!B6="Jövök :)",'Jelenlét'!$Z6,"") -> 2411.1111 | C6: =IF('Jelenlét'!C6="Jövök :)",'Jelenlét'!$Z6,"") | D6: =IF('Jelenlét'!D6="Jövök :)",'Jelenlét'!$Z6,"") | E6: =IF('Jelenlét'!E6="Jövök :)",'Jelenlét'!$Z6,"") | F6: =IF('Jelenlét'!F6="Jövök :)",'Jelenlét'!$Z6,"") -> 2411.1111 | G6: =IF('Jelenlét'!G6="Jövök :)",'Jelenlét'!$Z6,"") -> 2411.1111 | H6: =IF('Jelenlét'!H6="Jövök :)",'Jelenlét'!$Z6,"") -> 2411.1111 | I6: =IF('Jelenlét'!I6="Jövök :)",'Jelenlét'!$Z6,"") -> 2411.1111 | ... R6: =IF('Jelenlét'!R6="Jövök :)",'Jelenlét'!$Z6,"") -> 2411.1111 | S6: =IF('Jelenlét'!Y6="Jövök :)",'Jelenlét'!AV6,"") | T6: =IF('Jelenlét'!Z6="Jövök :)",'Jelenlét'!AW6,"") | U6: =IF('Jelenlét'!AA6="Jövök :)",'Jelenlét'!AX6,"") | V6: =IF('Jelenlét'!AB6="Jövök :)",'Jelenlét'!AY6,"")
A7: 45629 | B7: =IF('Jelenlét'!B7="Jövök :)",'Jelenlét'!$Z7,"") | C7: =IF('Jelenlét'!C7="Jövök :)",'Jelenlét'!$Z7,"") | D7: =IF('Jelenlét'!D7="Jövök :)",'Jelenlét'!$Z7,"") -> 2712.5 | E7: =IF('Jelenlét'!E7="Jövök :)",'Jelenlét'!$Z7,"") | F7: =IF('Jelenlét'!F7="Jövök :)",'Jelenlét'!$Z7,"") -> 2712.5 | G7: =IF('Jelenlét'!G7="Jövök :)",'Jelenlét'!$Z7,"") -> 2712.5 | H7: =IF('Jelenlét'!H7="Jövök :)",'Jelenlét'!$Z7,"") | I7: =IF('Jelenlét'!I7="Jövök :)",'Jelenlét'!$Z7,"") -> 2712.5 | ... U7: =IF('Jelenlét'!U7="Jövök :)",'Jelenlét'!$Z7,"") | V7: =IF('Jelenlét'!AB7="Jövök :)",'Jelenlét'!AY7,"") | W7: ='Jelenlét'!W7* 'Jelenlét'!Z7 -> 2712.5
A8: 45636 | B8: =IF('Jelenlét'!B8="Jövök :)",'Jelenlét'!$Z8,"") -> 1669.2308 | C8: =IF('Jelenlét'!C8="Jövök :)",'Jelenlét'!$Z8,"") -> 1669.2308 | D8: =IF('Jelenlét'!D8="Jövök :)",'Jelenlét'!$Z8,"") -> 1669.2308 | E8: =IF('Jelenlét'!E8="Jövök :)",'Jelenlét'!$Z8,"") -> 1669.2308 | F8: =IF('Jelenlét'!F8="Jövök :)",'Jelenlét'!$Z8,"") -> 1669.2308 | G8: =IF('Jelenlét'!G8="Jövök :)",'Jelenlét'!$Z8,"") -> 1669.2308 | H8: =IF('Jelenlét'!H8="Jövök :)",'Jelenlét'!$Z8,"") | I8: =IF('Jelenlét'!I8="Jövök :)",'Jelenlét'!$Z8,"") | ... U8: =IF('Jelenlét'!U8="Jövök :)",'Jelenlét'!$Z8,"") | V8: =IF('Jelenlét'!AB8="Jövök :)",'Jelenlét'!AY8,"") | W8: ='Jelenlét'!W8* 'Jelenlét'!Z8 -> 3338.4615
A9: 45643 | B9: =IF('Jelenlét'!B9="Jövök :)",'Jelenlét'!$Z9,"") | C9: =IF('Jelenlét'!C9="Jövök :)",'Jelenlét'!$Z9,"") | D9: =IF('Jelenlét'!D9="Jövök :)",'Jelenlét'!$Z9,"") -> 2863.6364 | E9: =IF('Jelenlét'!E9="Jövök :)",'Jelenlét'!$Z9,"") -> 2863.6364 | F9: =IF('Jelenlét'!F9="Jövök :)",'Jelenlét'!$Z9,"") -> 2863.6364 | G9: =IF('Jelenlét'!G9="Jövök :)",'Jelenlét'!$Z9,"") -> 2863.6364 | H9: =IF('Jelenlét'!H9="Jövök :)",'Jelenlét'!$Z9,"") -> 2863.6364 | I9: =IF('Jelenlét'!I9="Jövök :)",'Jelenlét'!$Z9,"") | ... U9: =IF('Jelenlét'!U9="Jövök :)",'Jelenlét'!$Z9,"") -> 2863.6364 | V9: =IF('Jelenlét'!AB9="Jövök :)",'Jelenlét'!AY9,"") | W9: ='Jelenlét'!W9* 'Jelenlét'!Z9 -> 0
A10: 45664 | B10: =IF('Jelenlét'!B10="Jövök :)",'Jelenlét'!$Z10,"") | C10: =IF('Jelenlét'!C10="Jövök :)",'Jelenlét'!$Z10,"") | D10: =IF('Jelenlét'!D10="Jövök :)",'Jelenlét'!$Z10,"") -> 2642.5 | E10: =IF('Jelenlét'!E10="Jövök :)",'Jelenlét'!$Z10,"") | F10: =IF('Jelenlét'!F10="Jövök :)",'Jelenlét'!$Z10,"") | G10: =IF('Jelenlét'!G10="Jövök :)",'Jelenlét'!$Z10,"") -> 2642.5 | H10: =IF('Jelenlét'!H10="Jövök :)",'Jelenlét'!$Z10,"") -> 2642.5 | I10: =IF('Jelenlét'!I10="Jövök :)",'Jelenlét'!$Z10,"") -> 2642.5 | ... U10: =IF('Jelenlét'!U10="Jövök :)",'Jelenlét'!$Z10,"") -> 2642.5 | V10: =IF('Jelenlét'!AB10="Jövök :)",'Jelenlét'!AY10,"") | W10: ='Jelenlét'!W10* 'Jelenlét'!Z10 -> 0
A11: 45671 | B11: =IF('Jelenlét'!B11="Jövök :)",'Jelenlét'!$Z11,"") | C11: =IF('Jelenlét'!C11="Jövök :)",'Jelenlét'!$Z11,"") -> 2114 | D11: =IF('Jelenlét'!D11="Jövök :)",'Jelenlét'!$Z11,"") -> 2114 | E11: =IF('Jelenlét'!E11="Jövök :)",'Jelenlét'!$Z11,"") -> 2114 | F11: =IF('Jelenlét'!F11="Jövök :)",'Jelenlét'!$Z11,"") | G11: =IF('Jelenlét'!G11="Jövök :)",'Jelenlét'!$Z11,"") -> 2114 | H11: =IF('Jelenlét'!H11="Jövök :)",'Jelenlét'!$Z11,"") | I11: =IF('Jelenlét'!I11="Jövök :)",'Jelenlét'!$Z11,"") -> 2114 | ... U11: =IF('Jelenlét'!U11="Jövök :)",'Jelenlét'!$Z11,"") -> 2114 | V11: =IF('Jelenlét'!AB11="Jövök :)",'Jelenlét'!AY11,"") | W11: ='Jelenlét'!W11* 'Jelenlét'!Z11 -> 0
A12: 45678 | B12: =IF('Jelenlét'!B12="Jövök :)",'Jelenlét'!$Z12,"") | C12: =IF('Jelenlét'!C12="Jövök :)",'Jelenlét'!$Z12,"") -> 1921.8182 | D12: =IF('Jelenlét'!D12="Jövök :)",'Jelenlét'!$Z12,"") | E12: =IF('Jelenlét'!E12="Jövök :)",'Jelenlét'!$Z12,"") -> 1921.8182 | F12: =IF('Jelenlét'!F12="Jövök :)",'Jelenlét'!$Z12,"") | G12: =IF('Jelenlét'!G12="Jövök :)",'Jelenlét'!$Z12,"") -> 1921.8182 | H12: =IF('Jelenlét'!H12="Jövök :)",'Jelenlét'!$Z12,"") | I12: =IF('Jelenlét'!I12="Jövök :)",'Jelenlét'!$Z12,"") -> 1921.8182 | ... U12: =IF('Jelenlét'!U12="Jövök :)",'Jelenlét'!$Z12,"") -> 1921.8182 | V12: =IF('Jelenlét'!AB12="Jövök :)",'Jelenlét'!AY12,"") | W12: ='Jelenlét'!W12* 'Jelenlét'!Z12 -> 1921.8182
A13: 45685 | B13: =IF('Jelenlét'!B13="Jövök :)",'Jelenlét'!$Z13,"") | C13: =IF('Jelenlét'!C13="Jövök :)",'Jelenlét'!$Z13,"") -> 2114 | D13: =IF('Jelenlét'!D13="Jövök :)",'Jelenlét'!$Z13,"") | E13: =IF('Jelenlét'!E13="Jövök :)",'Jelenlét'!$Z13,"") | F13: =IF('Jelenlét'!F13="Jövök :)",'Jelenlét'!$Z13,"") | G13: =IF('Jelenlét'!G13="Jövök :)",'Jelenlét'!$Z13,"") -> 2114 | H13: =IF('Jelenlét'!H13="Jövök :)",'Jelenlét'!$Z13,"") -> 2114 | I13: =IF('Jelenlét'!I13="Jövök :)",'Jelenlét'!$Z13,"") -> 2114 | ... U13: =IF('Jelenlét'!U13="Jövök :)",'Jelenlét'!$Z13,"") | V13: =IF('Jelenlét'!AB13="Jövök :)",'Jelenlét'!AY13,"") | W13: ='Jelenlét'!W13* 'Jelenlét'!Z13 -> 4228
A14: 45692 | B14: =IF('Jelenlét'!B14="Jövök :)",'Jelenlét'!$Z14,"") -> 2265.4545 | C14: =IF('Jelenlét'!C14="Jövök :)",'Jelenlét'!$Z14,"") | D14: =IF('Jelenlét'!D14="Jövök :)",'Jelenlét'!$Z14,"") | E14: =IF('Jelenlét'!E14="Jövök :)",'Jelenlét'!$Z14,"") | F14: =IF('Jelenlét'!F14="Jövök :)",'Jelenlét'!$Z14,"") | G14: =IF('Jelenlét'!G14="Jövök :)",'Jelenlét'!$Z14,"") -> 2265.4545 | H14: =IF('Jelenlét'!H14="Jövök :)",'Jelenlét'!$Z14,"") -> 2265.4545 | I14: =IF('Jelenlét'!I14="Jövök :)",'Jelenlét'!$Z14,"") -> 2265.4545 | ... U14: =IF('Jelenlét'!U14="Jövök :)",'Jelenlét'!$Z14,"") | V14: =IF('Jelenlét'!AB14="Jövök :)",'Jelenlét'!AY14,"") | W14: ='Jelenlét'!W14* 'Jelenlét'!Z14 -> 9061.8182
A15: 45699 | B15: =IF('Jelenlét'!B15="Jövök :)",'Jelenlét'!$Z15,"") -> 1780 | C15: =IF('Jelenlét'!C15="Jövök :)",'Jelenlét'!$Z15,"") -> 1780 | D15: =IF('Jelenlét'!D15="Jövök :)",'Jelenlét'!$Z15,"") -> 1780 | E15: =IF('Jelenlét'!E15="Jövök :)",'Jelenlét'!$Z15,"") | F15: =IF('Jelenlét'!F15="Jövök :)",'Jelenlét'!$Z15,"") -> 1780 | G15: =IF('Jelenlét'!G15="Jövök :)",'Jelenlét'!$Z15,"") -> 1780 | H15: =IF('Jelenlét'!H15="Jövök :)",'Jelenlét'!$Z15,"") -> 1780 | I15: =IF('Jelenlét'!I15="Jövök :)",'Jelenlét'!$Z15,"") -> 1780 | ... U15: =IF('Jelenlét'!U15="Jövök :)",'Jelenlét'!$Z15,"") | V15: =IF('Jelenlét'!AB15="Jövök :)",'Jelenlét'!AY15,"") | W15: ='Jelenlét'!W15* 'Jelenlét'!Z15 -> 3560
A16: 45706 | B16: =IF('Jelenlét'!B16="Jövök :)",'Jelenlét'!$Z16,"") | C16: =IF('Jelenlét'!C16="Jövök :)",'Jelenlét'!$Z16,"") -> 2076.6667 | D16: =IF('Jelenlét'!D16="Jövök :)",'Jelenlét'!$Z16,"") -> 2076.6667 | E16: =IF('Jelenlét'!E16="Jövök :)",'Jelenlét'!$Z16,"") | F16: =IF('Jelenlét'!F16="Jövök :)",'Jelenlét'!$Z16,"") -> 2076.6667 | G16: =IF('Jelenlét'!G16="Jövök :)",'Jelenlét'!$Z16,"") -> 2076.6667 | H16: =IF('Jelenlét'!H16="Jövök :)",'Jelenlét'!$Z16,"") -> 2076.6667 | I16: =IF('Jelenlét'!I16="Jövök :)",'Jelenlét'!$Z16,"") -> 2076.6667 | ... U16: =IF('Jelenlét'!U16="Jövök :)",'Jelenlét'!$Z16,"") -> 2076.6667 | V16: =IF('Jelenlét'!AB16="Jövök :)",'Jelenlét'!AY16,"") | W16: ='Jelenlét'!W16* 'Jelenlét'!Z16 -> 2076.6667
A17: 45713 | B17: =IF('Jelenlét'!B17="Jövök :)",'Jelenlét'!$Z17,"") | C17: =IF('Jelenlét'!C17="Jövök :)",'Jelenlét'!$Z17,"") -> 2492 | D17: =IF('Jelenlét'!D17="Jövök :)",'Jelenlét'!$Z17,"") -> 2492 | E17: =IF('Jelenlét'!E17="Jövök :)",'Jelenlét'!$Z17,"") | F17: =IF('Jelenlét'!F17="Jövök :)",'Jelenlét'!$Z17,"") -> 2492 | G17: =IF('Jelenlét'!G17="Jövök :)",'Jelenlét'!$Z17,"") -> 2492 | H17: =IF('Jelenlét'!H17="Jövök :)",'Jelenlét'!$Z17,"") -> 2492 | I17: =IF('Jelenlét'!I17="Jövök :)",'Jelenlét'!$Z17,"") -> 2492 | ... U17: =IF('Jelenlét'!U17="Jövök :)",'Jelenlét'!$Z17,"") -> 2492 | V17: =IF('Jelenlét'!AB17="Jövök :)",'Jelenlét'!AY17,"") | W17: ='Jelenlét'!W17* 'Jelenlét'!Z17 -> 0
A18: 45720 | B18: =IF('Jelenlét'!B18>=1,'Jelenlét'!B18*'Jelenlét'!$Z18,"") -> 1968.75 | C18: =IF('Jelenlét'!C18>=1,'Jelenlét'!C18*'Jelenlét'!$Z18,"") | D18: =IF('Jelenlét'!D18>=1,'Jelenlét'!D18*'Jelenlét'!$Z18,"") | E18: =IF('Jelenlét'!E18>=1,'Jelenlét'!E18*'Jelenlét'!$Z18,"") | F18: =IF('Jelenlét'!F18>=1,'Jelenlét'!F18*'Jelenlét'!$Z18,"") -> 1968.75 | G18: =IF('Jelenlét'!G18>=1,'Jelenlét'!G18*'Jelenlét'!$Z18,"") -> 3937.5 | H18: =IF('Jelenlét'!H18>=1,'Jelenlét'!H18*'Jelenlét'!$Z18,"") -> 1968.75 | I18: =IF('Jelenlét'!I18>=1,'Jelenlét'!I18*'Jelenlét'!$Z18,"") -> 1968.75 | ... U18: =IF('Jelenlét'!U18>=1,'Jelenlét'!U18*'Jelenlét'!$Z18,"") -> 1968.75 | V18: =IF('Jelenlét'!AB18="Jövök :)",'Jelenlét'!AY18,"") | W18: ='Jelenlét'!W18* 'Jelenlét'!Z18 -> #VALUE!
A19: 45727 | B19: =IF('Jelenlét'!B19>=1,'Jelenlét'!B19*'Jelenlét'!$Z19,"") | C19: =IF('Jelenlét'!C19>=1,'Jelenlét'!C19*'Jelenlét'!$Z19,"") | D19: =IF('Jelenlét'!D19>=1,'Jelenlét'!D19*'Jelenlét'!$Z19,"") -> 2625 | E19: =IF('Jelenlét'!E19>=1,'Jelenlét'!E19*'Jelenlét'!$Z19,"") | F19: =IF('Jelenlét'!F19>=1,'Jelenlét'!F19*'Jelenlét'!$Z19,"") -> 2625 | G19: =IF('Jelenlét'!G19>=1,'Jelenlét'!G19*'Jelenlét'!$Z19,"") -> 2625 | H19: =IF('Jelenlét'!H19>=1,'Jelenlét'!H19*'Jelenlét'!$Z19,"") -> 2625 | I19: =IF('Jelenlét'!I19>=1,'Jelenlét'!I19*'Jelenlét'!$Z19,"") -> 2625 | ... U19: =IF('Jelenlét'!U19>=1,'Jelenlét'!U19*'Jelenlét'!$Z19,"") -> 2625 | V19: =IF('Jelenlét'!AB19="Jövök :)",'Jelenlét'!AY19,"") | W19: ='Jelenlét'!W19* 'Jelenlét'!Z19 -> 0
A20: 45734 | B20: =IF('Jelenlét'!B20>=1,'Jelenlét'!B20*'Jelenlét'!$Z20,"") | C20: =IF('Jelenlét'!C20>=1,'Jelenlét'!C20*'Jelenlét'!$Z20,"") -> 1817.3077 | D20: =IF('Jelenlét'!D20>=1,'Jelenlét'!D20*'Jelenlét'!$Z20,"") -> 1817.3077 | E20: =IF('Jelenlét'!E20>=1,'Jelenlét'!E20*'Jelenlét'!$Z20,"") -> 1817.3077 | F20: =IF('Jelenlét'!F20>=1,'Jelenlét'!F20*'Jelenlét'!$Z20,"") -> 1817.3077 | G20: =IF('Jelenlét'!G20>=1,'Jelenlét'!G20*'Jelenlét'!$Z20,"") -> 3634.6154 | H20: =IF('Jelenlét'!H20>=1,'Jelenlét'!H20*'Jelenlét'!$Z20,"") -> 1817.3077 | I20: =IF('Jelenlét'!I20>=1,'Jelenlét'!I20*'Jelenlét'!$Z20,"") -> 1817.3077 | ... U20: =IF('Jelenlét'!U20>=1,'Jelenlét'!U20*'Jelenlét'!$Z20,"") -> 1817.3077 | V20: =IF('Jelenlét'!AB20="Jövök :)",'Jelenlét'!AY20,"") | W20: ='Jelenlét'!W20* 'Jelenlét'!Z20 -> 0
A21: 45741 | B21: =IF('Jelenlét'!B21>=1,'Jelenlét'!B21*'Jelenlét'!$Z21,"") | C21: =IF('Jelenlét'!C21>=1,'Jelenlét'!C21*'Jelenlét'!$Z21,"") -> 1817.3077 | D21: =IF('Jelenlét'!D21>=1,'Jelenlét'!D21*'Jelenlét'!$Z21,"") -> 1817.3077 | E21: =IF('Jelenlét'!E21>=1,'Jelenlét'!E21*'Jelenlét'!$Z21,"") | F21: =IF('Jelenlét'!F21>=1,'Jelenlét'!F21*'Jelenlét'!$Z21,"") -> 1817.3077 | G21: =IF('Jelenlét'!G21>=1,'Jelenlét'!G21*'Jelenlét'!$Z21,"") -> 1817.3077 | H21: =IF('Jelenlét'!H21>=1,'Jelenlét'!H21*'Jelenlét'!$Z21,"") -> 1817.3077 | I21: =IF('Jelenlét'!I21>=1,'Jelenlét'!I21*'Jelenlét'!$Z21,"") -> 1817.3077 | ... U21: =IF('Jelenlét'!U21>=1,'Jelenlét'!U21*'Jelenlét'!$Z21,"") -> 1817.3077 | V21: =IF('Jelenlét'!AB21="Jövök :)",'Jelenlét'!AY21,"") | W21: ='Jelenlét'!W21* 'Jelenlét'!Z21 -> 0
A22: 45748 | B22: =IF('Jelenlét'!B22>=1,'Jelenlét'!B22*'Jelenlét'!$Z22,"") | C22: =IF('Jelenlét'!C22>=1,'Jelenlét'!C22*'Jelenlét'!$Z22,"") -> 2245.6 | D22: =IF('Jelenlét'!D22>=1,'Jelenlét'!D22*'Jelenlét'!$Z22,"") | E22: =IF('Jelenlét'!E22>=1,'Jelenlét'!E22*'Jelenlét'!$Z22,"") | F22: =IF('Jelenlét'!F22>=1,'Jelenlét'!F22*'Jelenlét'!$Z22,"") -> 2245.6 | G22: =IF('Jelenlét'!G22>=1,'Jelenlét'!G22*'Jelenlét'!$Z22,"") -> 6736.8 | H22: =IF('Jelenlét'!H22>=1,'Jelenlét'!H22*'Jelenlét'!$Z22,"") -> 2245.6 | I22: =IF('Jelenlét'!I22>=1,'Jelenlét'!I22*'Jelenlét'!$Z22,"") -> 2245.6 | ... U22: =IF('Jelenlét'!U22>=1,'Jelenlét'!U22*'Jelenlét'!$Z22,"") -> 2245.6 | V22: =IF('Jelenlét'!AB22="Jövök :)",'Jelenlét'!AY22,"")
A23: 45755 | B23: =IF('Jelenlét'!B23>=1,'Jelenlét'!B23*'Jelenlét'!$Z23,"") | C23: =IF('Jelenlét'!C23>=1,'Jelenlét'!C23*'Jelenlét'!$Z23,"") | D23: =IF('Jelenlét'!D23>=1,'Jelenlét'!D23*'Jelenlét'!$Z23,"") -> 2041.4545 | E23: =IF('Jelenlét'!E23>=1,'Jelenlét'!E23*'Jelenlét'!$Z23,"") | F23: =IF('Jelenlét'!F23>=1,'Jelenlét'!F23*'Jelenlét'!$Z23,"") | G23: =IF('Jelenlét'!G23>=1,'Jelenlét'!G23*'Jelenlét'!$Z23,"") -> 4082.9091 | H23: =IF('Jelenlét'!H23>=1,'Jelenlét'!H23*'Jelenlét'!$Z23,"") -> 2041.4545 | I23: =IF('Jelenlét'!I23>=1,'Jelenlét'!I23*'Jelenlét'!$Z23,"") -> 2041.4545 | ... U23: =IF('Jelenlét'!U23>=1,'Jelenlét'!U23*'Jelenlét'!$Z23,"") -> 2041.4545 | V23: =IF('Jelenlét'!AB23="Jövök :)",'Jelenlét'!AY23,"")
A24: 45762 | B24: =IF('Jelenlét'!B24>=1,'Jelenlét'!B24*'Jelenlét'!$Z24,"") | C24: =IF('Jelenlét'!C24>=1,'Jelenlét'!C24*'Jelenlét'!$Z24,"") | D24: =IF('Jelenlét'!D24>=1,'Jelenlét'!D24*'Jelenlét'!$Z24,"") -> 1871.3333 | E24: =IF('Jelenlét'!E24>=1,'Jelenlét'!E24*'Jelenlét'!$Z24,"") -> 3742.6667 | F24: =IF('Jelenlét'!F24>=1,'Jelenlét'!F24*'Jelenlét'!$Z24,"") -> 1871.3333 | G24: =IF('Jelenlét'!G24>=1,'Jelenlét'!G24*'Jelenlét'!$Z24,"") -> 1871.3333 | H24: =IF('Jelenlét'!H24>=1,'Jelenlét'!H24*'Jelenlét'!$Z24,"") -> 1871.3333 | I24: =IF('Jelenlét'!I24>=1,'Jelenlét'!I24*'Jelenlét'!$Z24,"") -> 1871.3333 | ... U24: =IF('Jelenlét'!U24>=1,'Jelenlét'!U24*'Jelenlét'!$Z24,"") -> 1871.3333 | V24: =IF('Jelenlét'!AB24="Jövök :)",'Jelenlét'!AY24,"")
A25: 45769 | B25: =IF('Jelenlét'!B25>=1,'Jelenlét'!B25*'Jelenlét'!$Z25,"") | C25: =IF('Jelenlét'!C25>=1,'Jelenlét'!C25*'Jelenlét'!$Z25,"") -> 2245.6 | D25: =IF('Jelenlét'!D25>=1,'Jelenlét'!D25*'Jelenlét'!$Z25,"") | E25: =IF('Jelenlét'!E25>=1,'Jelenlét'!E25*'Jelenlét'!$Z25,"") | F25: =IF('Jelenlét'!F25>=1,'Jelenlét'!F25*'Jelenlét'!$Z25,"") | G25: =IF('Jelenlét'!G25>=1,'Jelenlét'!G25*'Jelenlét'!$Z25,"") | H25: =IF('Jelenlét'!H25>=1,'Jelenlét'!H25*'Jelenlét'!$Z25,"") -> 2245.6 | I25: =IF('Jelenlét'!I25>=1,'Jelenlét'!I25*'Jelenlét'!$Z25,"") -> 2245.6 | ... U25: =IF('Jelenlét'!U25>=1,'Jelenlét'!U25*'Jelenlét'!$Z25,"") -> 2245.6 | V25: =IF('Jelenlét'!AB25="Jövök :)",'Jelenlét'!AY25,"")
A26: 45776 | B26: =IF('Jelenlét'!B26>=1,'Jelenlét'!B26*'Jelenlét'!$Z26,"") | C26: =IF('Jelenlét'!C26>=1,'Jelenlét'!C26*'Jelenlét'!$Z26,"") | D26: =IF('Jelenlét'!D26>=1,'Jelenlét'!D26*'Jelenlét'!$Z26,"") -> 1727.3846 | E26: =IF('Jelenlét'!E26>=1,'Jelenlét'!E26*'Jelenlét'!$Z26,"") | F26: =IF('Jelenlét'!F26>=1,'Jelenlét'!F26*'Jelenlét'!$Z26,"") -> 1727.3846 | G26: =IF('Jelenlét'!G26>=1,'Jelenlét'!G26*'Jelenlét'!$Z26,"") -> 3454.7692 | H26: =IF('Jelenlét'!H26>=1,'Jelenlét'!H26*'Jelenlét'!$Z26,"") -> 1727.3846 | I26: =IF('Jelenlét'!I26>=1,'Jelenlét'!I26*'Jelenlét'!$Z26,"") -> 1727.3846 | ... U26: =IF('Jelenlét'!U26>=1,'Jelenlét'!U26*'Jelenlét'!$Z26,"") -> 1727.3846 | V26: =IF('Jelenlét'!AB26="Jövök :)",'Jelenlét'!AY26,"")
A27: 45783 | B27: =IF('Jelenlét'!B27>=1,'Jelenlét'!B27*'Jelenlét'!$Z27,"") | C27: =IF('Jelenlét'!C27>=1,'Jelenlét'!C27*'Jelenlét'!$Z27,"") -> 2566.6667 | D27: =IF('Jelenlét'!D27>=1,'Jelenlét'!D27*'Jelenlét'!$Z27,"") -> 2566.6667 | E27: =IF('Jelenlét'!E27>=1,'Jelenlét'!E27*'Jelenlét'!$Z27,"") | F27: =IF('Jelenlét'!F27>=1,'Jelenlét'!F27*'Jelenlét'!$Z27,"") -> 2566.6667 | G27: =IF('Jelenlét'!G27>=1,'Jelenlét'!G27*'Jelenlét'!$Z27,"") -> 2566.6667 | H27: =IF('Jelenlét'!H27>=1,'Jelenlét'!H27*'Jelenlét'!$Z27,"") -> 2566.6667 | I27: =IF('Jelenlét'!I27>=1,'Jelenlét'!I27*'Jelenlét'!$Z27,"") -> 2566.6667 | ... U27: =IF('Jelenlét'!U27>=1,'Jelenlét'!U27*'Jelenlét'!$Z27,"") -> 2566.6667 | V27: =IF('Jelenlét'!AB27="Jövök :)",'Jelenlét'!AY27,"")
A28: 45790 | B28: =IF('Jelenlét'!B28>=1,'Jelenlét'!B28*'Jelenlét'!$Z28,"") | C28: =IF('Jelenlét'!C28>=1,'Jelenlét'!C28*'Jelenlét'!$Z28,"") | D28: =IF('Jelenlét'!D28>=1,'Jelenlét'!D28*'Jelenlét'!$Z28,"") -> 2566.6667 | E28: =IF('Jelenlét'!E28>=1,'Jelenlét'!E28*'Jelenlét'!$Z28,"") | F28: =IF('Jelenlét'!F28>=1,'Jelenlét'!F28*'Jelenlét'!$Z28,"") -> 2566.6667 | G28: =IF('Jelenlét'!G28>=1,'Jelenlét'!G28*'Jelenlét'!$Z28,"") -> 2566.6667 | H28: =IF('Jelenlét'!H28>=1,'Jelenlét'!H28*'Jelenlét'!$Z28,"") | I28: =IF('Jelenlét'!I28>=1,'Jelenlét'!I28*'Jelenlét'!$Z28,"") | ... U28: =IF('Jelenlét'!U28>=1,'Jelenlét'!U28*'Jelenlét'!$Z28,"") -> 2566.6667 | V28: =IF('Jelenlét'!AB28="Jövök :)",'Jelenlét'!AY28,"")
A29: 45797 | B29: =IF('Jelenlét'!B29>=1,'Jelenlét'!B29*'Jelenlét'!$Z29,"") | C29: =IF('Jelenlét'!C29>=1,'Jelenlét'!C29*'Jelenlét'!$Z29,"") -> 2566.6667 | D29: =IF('Jelenlét'!D29>=1,'Jelenlét'!D29*'Jelenlét'!$Z29,"") | E29: =IF('Jelenlét'!E29>=1,'Jelenlét'!E29*'Jelenlét'!$Z29,"") | F29: =IF('Jelenlét'!F29>=1,'Jelenlét'!F29*'Jelenlét'!$Z29,"") | G29: =IF('Jelenlét'!G29>=1,'Jelenlét'!G29*'Jelenlét'!$Z29,"") -> 2566.6667 | H29: =IF('Jelenlét'!H29>=1,'Jelenlét'!H29*'Jelenlét'!$Z29,"") -> 2566.6667 | I29: =IF('Jelenlét'!I29>=1,'Jelenlét'!I29*'Jelenlét'!$Z29,"") | ... U29: =IF('Jelenlét'!U29>=1,'Jelenlét'!U29*'Jelenlét'!$Z29,"") | V29: =IF('Jelenlét'!AB29="Jövök :)",'Jelenlét'!AY29,"")
A30: 45804 | B30: =IF('Jelenlét'!B30>=1,'Jelenlét'!B30*'Jelenlét'!$Z30,"") | C30: =IF('Jelenlét'!C30>=1,'Jelenlét'!C30*'Jelenlét'!$Z30,"") -> 1650 | D30: =IF('Jelenlét'!D30>=1,'Jelenlét'!D30*'Jelenlét'!$Z30,"") -> 1650 | E30: =IF('Jelenlét'!E30>=1,'Jelenlét'!E30*'Jelenlét'!$Z30,"") -> 3300 | F30: =IF('Jelenlét'!F30>=1,'Jelenlét'!F30*'Jelenlét'!$Z30,"") -> 1650 | G30: =IF('Jelenlét'!G30>=1,'Jelenlét'!G30*'Jelenlét'!$Z30,"") -> 1650 | H30: =IF('Jelenlét'!H30>=1,'Jelenlét'!H30*'Jelenlét'!$Z30,"") -> 1650 | I30: =IF('Jelenlét'!I30>=1,'Jelenlét'!I30*'Jelenlét'!$Z30,"") -> 1650 | ... V30: =IF('Jelenlét'!V30>=1,'Jelenlét'!V30*'Jelenlét'!$Z30,"")
A31: 45811 | B31: =IF('Jelenlét'!B31>=1,'Jelenlét'!B31*'Jelenlét'!$Z31,"") | C31: =IF('Jelenlét'!C31>=1,'Jelenlét'!C31*'Jelenlét'!$Z31,"") | D31: =IF('Jelenlét'!D31>=1,'Jelenlét'!D31*'Jelenlét'!$Z31,"") | E31: =IF('Jelenlét'!E31>=1,'Jelenlét'!E31*'Jelenlét'!$Z31,"") | F31: =IF('Jelenlét'!F31>=1,'Jelenlét'!F31*'Jelenlét'!$Z31,"") -> 2160.4545 | G31: =IF('Jelenlét'!G31>=1,'Jelenlét'!G31*'Jelenlét'!$Z31,"") -> 2160.4545 | H31: =IF('Jelenlét'!H31>=1,'Jelenlét'!H31*'Jelenlét'!$Z31,"") -> 2160.4545 | I31: =IF('Jelenlét'!I31>=1,'Jelenlét'!I31*'Jelenlét'!$Z31,"") -> 2160.4545 | ... V31: =IF('Jelenlét'!V31>=1,'Jelenlét'!V31*'Jelenlét'!$Z31,"")
A32: 45818 | B32: =IF('Jelenlét'!B32>=1,'Jelenlét'!B32*'Jelenlét'!$Z32,"") | C32: =IF('Jelenlét'!C32>=1,'Jelenlét'!C32*'Jelenlét'!$Z32,"") -> 1828.0769 | D32: =IF('Jelenlét'!D32>=1,'Jelenlét'!D32*'Jelenlét'!$Z32,"") | E32: =IF('Jelenlét'!E32>=1,'Jelenlét'!E32*'Jelenlét'!$Z32,"") | F32: =IF('Jelenlét'!F32>=1,'Jelenlét'!F32*'Jelenlét'!$Z32,"") -> 1828.0769 | G32: =IF('Jelenlét'!G32>=1,'Jelenlét'!G32*'Jelenlét'!$Z32,"") -> 1828.0769 | H32: =IF('Jelenlét'!H32>=1,'Jelenlét'!H32*'Jelenlét'!$Z32,"") -> 1828.0769 | I32: =IF('Jelenlét'!I32>=1,'Jelenlét'!I32*'Jelenlét'!$Z32,"") -> 1828.0769 | ... V32: =IF('Jelenlét'!V32>=1,'Jelenlét'!V32*'Jelenlét'!$Z32,"")
A33: 45825 | B33: =IF('Jelenlét'!B33>=1,'Jelenlét'!B33*'Jelenlét'!$Z33,"") | C33: =IF('Jelenlét'!C33>=1,'Jelenlét'!C33*'Jelenlét'!$Z33,"") -> 1980.4167 | D33: =IF('Jelenlét'!D33>=1,'Jelenlét'!D33*'Jelenlét'!$Z33,"") -> 1980.4167 | E33: =IF('Jelenlét'!E33>=1,'Jelenlét'!E33*'Jelenlét'!$Z33,"") | F33: =IF('Jelenlét'!F33>=1,'Jelenlét'!F33*'Jelenlét'!$Z33,"") -> 1980.4167 | G33: =IF('Jelenlét'!G33>=1,'Jelenlét'!G33*'Jelenlét'!$Z33,"") -> 1980.4167 | H33: =IF('Jelenlét'!H33>=1,'Jelenlét'!H33*'Jelenlét'!$Z33,"") -> 1980.4167 | I33: =IF('Jelenlét'!I33>=1,'Jelenlét'!I33*'Jelenlét'!$Z33,"") -> 1980.4167 | ... V33: =IF('Jelenlét'!V33>=1,'Jelenlét'!V33*'Jelenlét'!$Z33,"")
A34: 45832 | B34: =IF('Jelenlét'!B34>=1,'Jelenlét'!B34*'Jelenlét'!$Z34,"") | C34: =IF('Jelenlét'!C34>=1,'Jelenlét'!C34*'Jelenlét'!$Z34,"") -> 1697.5 | D34: =IF('Jelenlét'!D34>=1,'Jelenlét'!D34*'Jelenlét'!$Z34,"") -> 1697.5 | E34: =IF('Jelenlét'!E34>=1,'Jelenlét'!E34*'Jelenlét'!$Z34,"") | F34: =IF('Jelenlét'!F34>=1,'Jelenlét'!F34*'Jelenlét'!$Z34,"") -> 1697.5 | G34: =IF('Jelenlét'!G34>=1,'Jelenlét'!G34*'Jelenlét'!$Z34,"") -> 1697.5 | H34: =IF('Jelenlét'!H34>=1,'Jelenlét'!H34*'Jelenlét'!$Z34,"") -> 1697.5 | I34: =IF('Jelenlét'!I34>=1,'Jelenlét'!I34*'Jelenlét'!$Z34,"") -> 1697.5 | ... V34: =IF('Jelenlét'!V34>=1,'Jelenlét'!V34*'Jelenlét'!$Z34,"") -> 1697.5
A35: 45839 | B35: =IF('Jelenlét'!B35>=1,'Jelenlét'!B35*'Jelenlét'!$Z35,"") | C35: =IF('Jelenlét'!C35>=1,'Jelenlét'!C35*'Jelenlét'!$Z35,"") -> 1609.0667 | D35: =IF('Jelenlét'!D35>=1,'Jelenlét'!D35*'Jelenlét'!$Z35,"") -> 1609.0667 | E35: =IF('Jelenlét'!E35>=1,'Jelenlét'!E35*'Jelenlét'!$Z35,"") -> 3218.1333 | F35: =IF('Jelenlét'!F35>=1,'Jelenlét'!F35*'Jelenlét'!$Z35,"") -> 1609.0667 | G35: =IF('Jelenlét'!G35>=1,'Jelenlét'!G35*'Jelenlét'!$Z35,"") -> 1609.0667 | H35: =IF('Jelenlét'!H35>=1,'Jelenlét'!H35*'Jelenlét'!$Z35,"") -> 1609.0667 | I35: =IF('Jelenlét'!I35>=1,'Jelenlét'!I35*'Jelenlét'!$Z35,"") -> 1609.0667 | ... V35: =IF('Jelenlét'!V35>=1,'Jelenlét'!V35*'Jelenlét'!$Z35,"") -> 1609.0667
A36: 45846 | B36: =IF('Jelenlét'!B36>=1,'Jelenlét'!B36*'Jelenlét'!$Z36,"") | C36: =IF('Jelenlét'!C36>=1,'Jelenlét'!C36*'Jelenlét'!$Z36,"") | D36: =IF('Jelenlét'!D36>=1,'Jelenlét'!D36*'Jelenlét'!$Z36,"") -> 1609.0667 | E36: =IF('Jelenlét'!E36>=1,'Jelenlét'!E36*'Jelenlét'!$Z36,"") | F36: =IF('Jelenlét'!F36>=1,'Jelenlét'!F36*'Jelenlét'!$Z36,"") -> 3218.1333 | G36: =IF('Jelenlét'!G36>=1,'Jelenlét'!G36*'Jelenlét'!$Z36,"") -> 3218.1333 | H36: =IF('Jelenlét'!H36>=1,'Jelenlét'!H36*'Jelenlét'!$Z36,"") | I36: =IF('Jelenlét'!I36>=1,'Jelenlét'!I36*'Jelenlét'!$Z36,"") -> 1609.0667 | ... V36: =IF('Jelenlét'!V36>=1,'Jelenlét'!V36*'Jelenlét'!$Z36,"") -> 1609.0667
A37: 45853 | B37: =IF('Jelenlét'!B37>=1,'Jelenlét'!B37*'Jelenlét'!$Z37,"") | C37: =IF('Jelenlét'!C37>=1,'Jelenlét'!C37*'Jelenlét'!$Z37,"") -> 2011.3333 | D37: =IF('Jelenlét'!D37>=1,'Jelenlét'!D37*'Jelenlét'!$Z37,"") | E37: =IF('Jelenlét'!E37>=1,'Jelenlét'!E37*'Jelenlét'!$Z37,"") | F37: =IF('Jelenlét'!F37>=1,'Jelenlét'!F37*'Jelenlét'!$Z37,"") -> 4022.6667 | G37: =IF('Jelenlét'!G37>=1,'Jelenlét'!G37*'Jelenlét'!$Z37,"") -> 4022.6667 | H37: =IF('Jelenlét'!H37>=1,'Jelenlét'!H37*'Jelenlét'!$Z37,"") | I37: =IF('Jelenlét'!I37>=1,'Jelenlét'!I37*'Jelenlét'!$Z37,"") | ... V37: =IF('Jelenlét'!V37>=1,'Jelenlét'!V37*'Jelenlét'!$Z37,"") -> 2011.3333
A38: 45860 | B38: =IF('Jelenlét'!B38>=1,'Jelenlét'!B38*'Jelenlét'!$Z38,"") | C38: =IF('Jelenlét'!C38>=1,'Jelenlét'!C38*'Jelenlét'!$Z38,"") -> 2011.3333 | D38: =IF('Jelenlét'!D38>=1,'Jelenlét'!D38*'Jelenlét'!$Z38,"") -> 2011.3333 | E38: =IF('Jelenlét'!E38>=1,'Jelenlét'!E38*'Jelenlét'!$Z38,"") | F38: =IF('Jelenlét'!F38>=1,'Jelenlét'!F38*'Jelenlét'!$Z38,"") -> 4022.6667 | G38: =IF('Jelenlét'!G38>=1,'Jelenlét'!G38*'Jelenlét'!$Z38,"") | H38: =IF('Jelenlét'!H38>=1,'Jelenlét'!H38*'Jelenlét'!$Z38,"") | I38: =IF('Jelenlét'!I38>=1,'Jelenlét'!I38*'Jelenlét'!$Z38,"") | ... V38: =IF('Jelenlét'!V38>=1,'Jelenlét'!V38*'Jelenlét'!$Z38,"")
A39: 45867 | B39: =IF('Jelenlét'!B39>=1,'Jelenlét'!B39*'Jelenlét'!$Z39,"") | C39: =IF('Jelenlét'!C39>=1,'Jelenlét'!C39*'Jelenlét'!$Z39,"") | D39: =IF('Jelenlét'!D39>=1,'Jelenlét'!D39*'Jelenlét'!$Z39,"") -> 6034 | E39: =IF('Jelenlét'!E39>=1,'Jelenlét'!E39*'Jelenlét'!$Z39,"") -> 4022.6667 | F39: =IF('Jelenlét'!F39>=1,'Jelenlét'!F39*'Jelenlét'!$Z39,"") -> 2011.3333 | G39: =IF('Jelenlét'!G39>=1,'Jelenlét'!G39*'Jelenlét'!$Z39,"") -> 2011.3333 | H39: =IF('Jelenlét'!H39>=1,'Jelenlét'!H39*'Jelenlét'!$Z39,"") -> 2011.3333 | I39: =IF('Jelenlét'!I39>=1,'Jelenlét'!I39*'Jelenlét'!$Z39,"") -> 2011.3333 | ... V39: =IF('Jelenlét'!V39>=1,'Jelenlét'!V39*'Jelenlét'!$Z39,"") -> 2011.3333
A40: 45874 | B40: =IF('Jelenlét'!B40>=1,'Jelenlét'!B40*'Jelenlét'!$Z40,"") | C40: =IF('Jelenlét'!C40>=1,'Jelenlét'!C40*'Jelenlét'!$Z40,"") | D40: =IF('Jelenlét'!D40>=1,'Jelenlét'!D40*'Jelenlét'!$Z40,"") -> 7387.6923 | E40: =IF('Jelenlét'!E40>=1,'Jelenlét'!E40*'Jelenlét'!$Z40,"") -> 5540.7692 | F40: =IF('Jelenlét'!F40>=1,'Jelenlét'!F40*'Jelenlét'!$Z40,"") -> 1846.9231 | G40: =IF('Jelenlét'!G40>=1,'Jelenlét'!G40*'Jelenlét'!$Z40,"") | H40: =IF('Jelenlét'!H40>=1,'Jelenlét'!H40*'Jelenlét'!$Z40,"") -> 1846.9231 | I40: =IF('Jelenlét'!I40>=1,'Jelenlét'!I40*'Jelenlét'!$Z40,"") | ... V40: =IF('Jelenlét'!V40>=1,'Jelenlét'!V40*'Jelenlét'!$Z40,"")
...

Sheet Összegzés
A1: Név: | B1: András Papp | C1: Anna Sengler | D1: Annamária Földváry | E1: Flóra & Boti | F1: Csanád Laczkó | G1: Csenge Domokos | H1: Detti Szabó | I1: Dóri Békási | J1: Gergely Márki | K1: Kilyénfalvi Júlia | L1: Kristóf szelényi | M1: Laura Piski | N1: Léna Piski | O1: Linda Antal | P1: Máté Lajer | Q1: Nóri Sásdi | R1: Laci Márki | S1: Kadosa Domokos | T1: Áron Szabó | U1: Máté Plank | V1: Lea Plank
A2: június | B2: =IF(COUNTIF('Jelenlét'!B31:B34,">1")=0,SUM('Számolás'!B31:B34),SUM('Számolás'!B31:B34)) -> 0 | C2: =IF(COUNTIF('Jelenlét'!C31:C34,">1")=0,SUM('Számolás'!C31:C34),SUM('Számolás'!C31:C34)) -> 5505.9936 | D2: =IF(COUNTIF('Jelenlét'!D31:D34,">1")=0,SUM('Számolás'!D31:D34),SUM('Számolás'!D31:D34)) -> 3677.9167 | E2: =IF(COUNTIF('Jelenlét'!E31:E34,">1")=0,SUM('Számolás'!E31:E34),SUM('Számolás'!E31:E34)) -> 0 | F2: =IF(COUNTIF('Jelenlét'!F31:F34,">1")=0,SUM('Számolás'!F31:F34),SUM('Számolás'!F31:F34)) -> 7666.4481 | G2: =IF(COUNTIF('Jelenlét'!G31:G34,">1")=0,SUM('Számolás'!G31:G34),SUM('Számolás'!G31:G34)) -> 7666.4481 | H2: =IF(COUNTIF('Jelenlét'!H31:H34,">1")=0,SUM('Számolás'!H31:H34),SUM('Számolás'!H31:H34)) -> 7666.4481 | I2: =IF(COUNTIF('Jelenlét'!I31:I34,">1")=0,SUM('Számolás'!I31:I34),SUM('Számolás'!I31:I34)) -> 7666.4481 | ... V2: =IF(COUNTIF('Jelenlét'!V31:V34,">1")=0,SUM('Számolás'!V31:V34),SUM('Számolás'!V31:V34)) -> 1697.5 | W2: =SUM(B2:V2) -> 95060
B3: =IF('Jelenlét'!B31>1,'Jelenlét'!B31-1 & "x" &'Jelenlét'!$Z31," ") | C3: =IF('Jelenlét'!C31>1,'Jelenlét'!C31-1 & "x" &'Jelenlét'!$Z31," ") | D3: =IF('Jelenlét'!D31>1,'Jelenlét'!D31-1 & "x" &'Jelenlét'!$Z31," ") | E3: =IF('Jelenlét'!E31>1,'Jelenlét'!E31-1 & "x" &'Jelenlét'!$Z31," ") | F3: =IF('Jelenlét'!F31>1,'Jelenlét'!F31-1 & "x" &'Jelenlét'!$Z31," ") | G3: =IF('Jelenlét'!G31>1,'Jelenlét'!G31-1 & "x" &'Jelenlét'!$Z31," ") | H3: =IF('Jelenlét'!H31>1,'Jelenlét'!H31-1 & "x" &'Jelenlét'!$Z31," ") | I3: =IF('Jelenlét'!I31>1,'Jelenlét'!I31-1 & "x" &'Jelenlét'!$Z31," ") | ... U3: =IF('Jelenlét'!U31>1,'Jelenlét'!U31-1 & "x" &'Jelenlét'!$Z31," ")
B4: =IF('Jelenlét'!B32>1,'Jelenlét'!B32-1 & "x" &'Jelenlét'!$Z32," ") | C4: =IF('Jelenlét'!C32>1,'Jelenlét'!C32-1 & "x" &'Jelenlét'!$Z32," ") | D4: =IF('Jelenlét'!D32>1,'Jelenlét'!D32-1 & "x" &'Jelenlét'!$Z32," ") | E4: =IF('Jelenlét'!E32>1,'Jelenlét'!E32-1 & "x" &'Jelenlét'!$Z32," ") | F4: =IF('Jelenlét'!F32>1,'Jelenlét'!F32-1 & "x" &'Jelenlét'!$Z32," ") | G4: =IF('Jelenlét'!G32>1,'Jelenlét'!G32-1 & "x" &'Jelenlét'!$Z32," ") | H4: =IF('Jelenlét'!H32>1,'Jelenlét'!H32-1 & "x" &'Jelenlét'!$Z32," ") | I4: =IF('Jelenlét'!I32>1,'Jelenlét'!I32-1 & "x" &'Jelenlét'!$Z32," ") | ... U4: =IF('Jelenlét'!U32>1,'Jelenlét'!U32-1 & "x" &'Jelenlét'!$Z32," ")
B5: =IF('Jelenlét'!B33>1,'Jelenlét'!B33-1 & "x" &'Jelenlét'!$Z33," ") | C5: =IF('Jelenlét'!C33>1,'Jelenlét'!C33-1 & "x" &'Jelenlét'!$Z33," ") | D5: =IF('Jelenlét'!D33>1,'Jelenlét'!D33-1 & "x" &'Jelenlét'!$Z33," ") | E5: =IF('Jelenlét'!E33>1,'Jelenlét'!E33-1 & "x" &'Jelenlét'!$Z33," ") | F5: =IF('Jelenlét'!F33>1,'Jelenlét'!F33-1 & "x" &'Jelenlét'!$Z33," ") | G5: =IF('Jelenlét'!G33>1,'Jelenlét'!G33-1 & "x" &'Jelenlét'!$Z33," ") | H5: =IF('Jelenlét'!H33>1,'Jelenlét'!H33-1 & "x" &'Jelenlét'!$Z33," ") | I5: =IF('Jelenlét'!I33>1,'Jelenlét'!I33-1 & "x" &'Jelenlét'!$Z33," ") | ... U5: =IF('Jelenlét'!U33>1,'Jelenlét'!U33-1 & "x" &'Jelenlét'!$Z33," ")
B6: =IF('Jelenlét'!B34>1,'Jelenlét'!B34-1 & "x" &'Jelenlét'!$Z34," ") | C6: =IF('Jelenlét'!C34>1,'Jelenlét'!C34-1 & "x" &'Jelenlét'!$Z34," ") | D6: =IF('Jelenlét'!D34>1,'Jelenlét'!D34-1 & "x" &'Jelenlét'!$Z34," ") | E6: =IF('Jelenlét'!E34>1,'Jelenlét'!E34-1 & "x" &'Jelenlét'!$Z34," ") | F6: =IF('Jelenlét'!F34>1,'Jelenlét'!F34-1 & "x" &'Jelenlét'!$Z34," ") | G6: =IF('Jelenlét'!G34>1,'Jelenlét'!G34-1 & "x" &'Jelenlét'!$Z34," ") | H6: =IF('Jelenlét'!H34>1,'Jelenlét'!H34-1 & "x" &'Jelenlét'!$Z34," ") | I6: =IF('Jelenlét'!I34>1,'Jelenlét'!I34-1 & "x" &'Jelenlét'!$Z34," ") | ... U6: =IF('Jelenlét'!U34>1,'Jelenlét'!U34-1 & "x" &'Jelenlét'!$Z34," ")
B7: FALSE | C7: FALSE | D7: FALSE | E7: FALSE | F7: FALSE | G7: FALSE | H7: FALSE | I7: FALSE | J7: FALSE | K7: FALSE | L7: FALSE | M7: FALSE | N7: FALSE | O7: FALSE | P7: FALSE | Q7: FALSE | R7: FALSE | S7: FALSE | T7: TRUE | U7: FALSE | V7: FALSE
A8: július | B8: =IF(COUNTIF('Jelenlét'!B35:B39,">1")=0,SUM('Számolás'!B35:B39),SUM('Számolás'!B35:B39)) -> 0 | C8: =IF(COUNTIF('Jelenlét'!C35:C39,">1")=0,SUM('Számolás'!C35:C39),SUM('Számolás'!C35:C39)) -> 5631.7333 | D8: =IF(COUNTIF('Jelenlét'!D35:D39,">1")=0,SUM('Számolás'!D35:D39),SUM('Számolás'!D35:D39)) -> 11263.467 | E8: =IF(COUNTIF('Jelenlét'!E35:E39,">1")=0,SUM('Számolás'!E35:E39),SUM('Számolás'!E35:E39)) -> 7240.8 | F8: =IF(COUNTIF('Jelenlét'!F35:F39,">1")=0,SUM('Számolás'!F35:F39),SUM('Számolás'!F35:F39)) -> 14883.867 | G8: =IF(COUNTIF('Jelenlét'!G35:G39,">1")=0,SUM('Számolás'!G35:G39),SUM('Számolás'!G35:G39)) -> 10861.2 | H8: =IF(COUNTIF('Jelenlét'!H35:H39,">1")=0,SUM('Számolás'!H35:H39),SUM('Számolás'!H35:H39)) -> 3620.4 | I8: =IF(COUNTIF('Jelenlét'!I35:I39,">1")=0,SUM('Számolás'!I35:I39),SUM('Számolás'!I35:I39)) -> 5229.4667 | ... V8: =IF(COUNTIF('Jelenlét'!V35:V39,">1")=0,SUM('Számolás'!V35:V39),SUM('Számolás'!V35:V39)) -> 7240.8 | W8: =SUM(B8:V8) -> 120680
B9: =IF('Jelenlét'!B35>1,'Jelenlét'!B35-1 & "x" &'Jelenlét'!$Z35," ") | C9: =IF('Jelenlét'!C35>1,'Jelenlét'!C35-1 & "x" &'Jelenlét'!$Z35," ") | D9: =IF('Jelenlét'!D35>1,'Jelenlét'!D35-1 & "x" &'Jelenlét'!$Z35," ") | E9: =IF('Jelenlét'!E35>1,'Jelenlét'!E35-1 & "x" &'Jelenlét'!$Z35," ") -> 1x1609,06666666667 | F9: =IF('Jelenlét'!F35>1,'Jelenlét'!F35-1 & "x" &'Jelenlét'!$Z35," ") | G9: =IF('Jelenlét'!G35>1,'Jelenlét'!G35-1 & "x" &'Jelenlét'!$Z35," ") | H9: =IF('Jelenlét'!H35>1,'Jelenlét'!H35-1 & "x" &'Jelenlét'!$Z35," ") | I9: =IF('Jelenlét'!I35>1,'Jelenlét'!I35-1 & "x" &'Jelenlét'!$Z35," ") | ... U9: =IF('Jelenlét'!U35>1,'Jelenlét'!U35-1 & "x" &'Jelenlét'!$Z35," ")
B10: =IF('Jelenlét'!B36>1,'Jelenlét'!B36-1 & "x" &'Jelenlét'!$Z36," ") | C10: =IF('Jelenlét'!C36>1,'Jelenlét'!C36-1 & "x" &'Jelenlét'!$Z36," ") | D10: =IF('Jelenlét'!D36>1,'Jelenlét'!D36-1 & "x" &'Jelenlét'!$Z36," ") | E10: =IF('Jelenlét'!E36>1,'Jelenlét'!E36-1 & "x" &'Jelenlét'!$Z36," ") | F10: =IF('Jelenlét'!F36>1,'Jelenlét'!F36-1 & "x" &'Jelenlét'!$Z36," ") -> 1x1609,06666666667 | G10: =IF('Jelenlét'!G36>1,'Jelenlét'!G36-1 & "x" &'Jelenlét'!$Z36," ") -> 1x1609,06666666667 | H10: =IF('Jelenlét'!H36>1,'Jelenlét'!H36-1 & "x" &'Jelenlét'!$Z36," ") | I10: =IF('Jelenlét'!I36>1,'Jelenlét'!I36-1 & "x" &'Jelenlét'!$Z36," ") | ... U10: =IF('Jelenlét'!U36>1,'Jelenlét'!U36-1 & "x" &'Jelenlét'!$Z36," ")
B11: =IF('Jelenlét'!B37>1,'Jelenlét'!B37-1 & "x" &'Jelenlét'!$Z37," ") | C11: =IF('Jelenlét'!C37>1,'Jelenlét'!C37-1 & "x" &'Jelenlét'!$Z37," ") | D11: =IF('Jelenlét'!D37>1,'Jelenlét'!D37-1 & "x" &'Jelenlét'!$Z37," ") | E11: =IF('Jelenlét'!E37>1,'Jelenlét'!E37-1 & "x" &'Jelenlét'!$Z37," ") | F11: =IF('Jelenlét'!F37>1,'Jelenlét'!F37-1 & "x" &'Jelenlét'!$Z37," ") -> 1x2011,33333333333 | G11: =IF('Jelenlét'!G37>1,'Jelenlét'!G37-1 & "x" &'Jelenlét'!$Z37," ") -> 1x2011,33333333333 | H11: =IF('Jelenlét'!H37>1,'Jelenlét'!H37-1 & "x" &'Jelenlét'!$Z37," ") | I11: =IF('Jelenlét'!I37>1,'Jelenlét'!I37-1 & "x" &'Jelenlét'!$Z37," ") | ... U11: =IF('Jelenlét'!U37>1,'Jelenlét'!U37-1 & "x" &'Jelenlét'!$Z37," ")
B12: =IF('Jelenlét'!B38>1,'Jelenlét'!B38-1 & "x" &'Jelenlét'!$Z38," ") | C12: =IF('Jelenlét'!C38>1,'Jelenlét'!C38-1 & "x" &'Jelenlét'!$Z38," ") | D12: =IF('Jelenlét'!D38>1,'Jelenlét'!D38-1 & "x" &'Jelenlét'!$Z38," ") | E12: =IF('Jelenlét'!E38>1,'Jelenlét'!E38-1 & "x" &'Jelenlét'!$Z38," ") | F12: =IF('Jelenlét'!F38>1,'Jelenlét'!F38-1 & "x" &'Jelenlét'!$Z38," ") -> 1x2011,33333333333 | G12: =IF('Jelenlét'!G38>1,'Jelenlét'!G38-1 & "x" &'Jelenlét'!$Z38," ") | H12: =IF('Jelenlét'!H38>1,'Jelenlét'!H38-1 & "x" &'Jelenlét'!$Z38," ") | I12: =IF('Jelenlét'!I38>1,'Jelenlét'!I38-1 & "x" &'Jelenlét'!$Z38," ") | ... U12: =IF('Jelenlét'!U38>1,'Jelenlét'!U38-1 & "x" &'Jelenlét'!$Z38," ")
B13: =IF('Jelenlét'!B39>1,'Jelenlét'!B39-1 & "x" &'Jelenlét'!$Z39," ") | C13: =IF('Jelenlét'!C39>1,'Jelenlét'!C39-1 & "x" &'Jelenlét'!$Z39," ") | D13: =IF('Jelenlét'!D39>1,'Jelenlét'!D39-1 & "x" &'Jelenlét'!$Z39," ") -> 2x2011,33333333333 | E13: =IF('Jelenlét'!E39>1,'Jelenlét'!E39-1 & "x" &'Jelenlét'!$Z39," ") -> 1x2011,33333333333 | F13: =IF('Jelenlét'!F39>1,'Jelenlét'!F39-1 & "x" &'Jelenlét'!$Z39," ") | G13: =IF('Jelenlét'!G39>1,'Jelenlét'!G39-1 & "x" &'Jelenlét'!$Z39," ") | H13: =IF('Jelenlét'!H39>1,'Jelenlét'!H39-1 & "x" &'Jelenlét'!$Z39," ") | I13: =IF('Jelenlét'!I39>1,'Jelenlét'!I39-1 & "x" &'Jelenlét'!$Z39," ") | ... U13: =IF('Jelenlét'!U39>1,'Jelenlét'!U39-1 & "x" &'Jelenlét'!$Z39," ")
B14: FALSE | C14: TRUE | D14: TRUE | E14: FALSE | F14: FALSE | G14: TRUE | H14: TRUE | I14: TRUE | J14: TRUE | K14: FALSE | L14: FALSE | M14: FALSE | N14: FALSE | O14: FALSE | P14: FALSE | Q14: TRUE | R14: FALSE | S14: TRUE | T14: TRUE | U14: TRUE | V14: TRUE
A15: Augusztus | B15: =IF(COUNTIF('Jelenlét'!B40:B43,">1")=0,SUM('Számolás'!B40:B43),SUM('Számolás'!B40:B43)) -> 0 | C15: =IF(COUNTIF('Jelenlét'!C40:C43,">1")=0,SUM('Számolás'!C40:C43),SUM('Számolás'!C40:C43)) -> 0 | D15: =IF(COUNTIF('Jelenlét'!D40:D43,">1")=0,SUM('Számolás'!D40:D43),SUM('Számolás'!D40:D43)) -> 7387.6923 | E15: =IF(COUNTIF('Jelenlét'!E40:E43,">1")=0,SUM('Számolás'!E40:E43),SUM('Számolás'!E40:E43)) -> 5540.7692 | F15: =IF(COUNTIF('Jelenlét'!F40:F43,">1")=0,SUM('Számolás'!F40:F43),SUM('Számolás'!F40:F43)) -> 3847.7564 | G15: =IF(COUNTIF('Jelenlét'!G40:G43,">1")=0,SUM('Számolás'!G40:G43),SUM('Számolás'!G40:G43)) -> 4001.6667 | H15: =IF(COUNTIF('Jelenlét'!H40:H43,">1")=0,SUM('Számolás'!H40:H43),SUM('Számolás'!H40:H43)) -> 3847.7564 | I15: =IF(COUNTIF('Jelenlét'!I40:I43,">1")=0,SUM('Számolás'!I40:I43),SUM('Számolás'!I40:I43)) -> 4001.6667 | ... V15: =IF(COUNTIF('Jelenlét'!V40:V43,">1")=0,SUM('Számolás'!V40:V43),SUM('Számolás'!V40:V43)) -> 2000.8333 | W15: =SUM(B15:V15) -> 72030
B16: =IF('Jelenlét'!B40>1,'Jelenlét'!B40-1 & "x" &'Jelenlét'!$Z40," ") | C16: =IF('Jelenlét'!C40>1,'Jelenlét'!C40-1 & "x" &'Jelenlét'!$Z40," ") | D16: =IF('Jelenlét'!D40>1,'Jelenlét'!D40-1 & "x" &'Jelenlét'!$Z40," ") -> 3x1846,92307692308 | E16: =IF('Jelenlét'!E40>1,'Jelenlét'!E40-1 & "x" &'Jelenlét'!$Z40," ") -> 2x1846,92307692308 | F16: =IF('Jelenlét'!F40>1,'Jelenlét'!F40-1 & "x" &'Jelenlét'!$Z40," ") | G16: =IF('Jelenlét'!G40>1,'Jelenlét'!G40-1 & "x" &'Jelenlét'!$Z40," ") | H16: =IF('Jelenlét'!H40>1,'Jelenlét'!H40-1 & "x" &'Jelenlét'!$Z40," ") | I16: =IF('Jelenlét'!I40>1,'Jelenlét'!I40-1 & "x" &'Jelenlét'!$Z40," ") | ... V16: =IF('Jelenlét'!V40>1,'Jelenlét'!V40-1 & "x" &'Jelenlét'!$Z40," ")
B17: =IF('Jelenlét'!B41>1,'Jelenlét'!B41-1 & "x" &'Jelenlét'!$Z41," ") | C17: =IF('Jelenlét'!C41>1,'Jelenlét'!C41-1 & "x" &'Jelenlét'!$Z41," ") | D17: =IF('Jelenlét'!D41>1,'Jelenlét'!D41-1 & "x" &'Jelenlét'!$Z41," ") | E17: =IF('Jelenlét'!E41>1,'Jelenlét'!E41-1 & "x" &'Jelenlét'!$Z41," ") | F17: =IF('Jelenlét'!F41>1,'Jelenlét'!F41-1 & "x" &'Jelenlét'!$Z41," ") | G17: =IF('Jelenlét'!G41>1,'Jelenlét'!G41-1 & "x" &'Jelenlét'!$Z41," ") | H17: =IF('Jelenlét'!H41>1,'Jelenlét'!H41-1 & "x" &'Jelenlét'!$Z41," ") | I17: =IF('Jelenlét'!I41>1,'Jelenlét'!I41-1 & "x" &'Jelenlét'!$Z41," ") | ... V17: =IF('Jelenlét'!V41>1,'Jelenlét'!V41-1 & "x" &'Jelenlét'!$Z41," ")
B18: =IF('Jelenlét'!B42>1,'Jelenlét'!B42-1 & "x" &'Jelenlét'!$Z42," ") | C18: =IF('Jelenlét'!C42>1,'Jelenlét'!C42-1 & "x" &'Jelenlét'!$Z42," ") | D18: =IF('Jelenlét'!D42>1,'Jelenlét'!D42-1 & "x" &'Jelenlét'!$Z42," ") | E18: =IF('Jelenlét'!E42>1,'Jelenlét'!E42-1 & "x" &'Jelenlét'!$Z42," ") | F18: =IF('Jelenlét'!F42>1,'Jelenlét'!F42-1 & "x" &'Jelenlét'!$Z42," ") | G18: =IF('Jelenlét'!G42>1,'Jelenlét'!G42-1 & "x" &'Jelenlét'!$Z42," ") | H18: =IF('Jelenlét'!H42>1,'Jelenlét'!H42-1 & "x" &'Jelenlét'!$Z42," ") | I18: =IF('Jelenlét'!I42>1,'Jelenlét'!I42-1 & "x" &'Jelenlét'!$Z42," ") | ... V18: =IF('Jelenlét'!V42>1,'Jelenlét'!V42-1 & "x" &'Jelenlét'!$Z42," ")
B19: =IF('Jelenlét'!B43>1,'Jelenlét'!B43-1 & "x" &'Jelenlét'!$Z43," ") | C19: =IF('Jelenlét'!C43>1,'Jelenlét'!C43-1 & "x" &'Jelenlét'!$Z43," ") | D19: =IF('Jelenlét'!D43>1,'Jelenlét'!D43-1 & "x" &'Jelenlét'!$Z43," ") | E19: =IF('Jelenlét'!E43>1,'Jelenlét'!E43-1 & "x" &'Jelenlét'!$Z43," ") | F19: =IF('Jelenlét'!F43>1,'Jelenlét'!F43-1 & "x" &'Jelenlét'!$Z43," ") | G19: =IF('Jelenlét'!G43>1,'Jelenlét'!G43-1 & "x" &'Jelenlét'!$Z43," ") | H19: =IF('Jelenlét'!H43>1,'Jelenlét'!H43-1 & "x" &'Jelenlét'!$Z43," ") | I19: =IF('Jelenlét'!I43>1,'Jelenlét'!I43-1 & "x" &'Jelenlét'!$Z43," ") | ... V19: =IF('Jelenlét'!V43>1,'Jelenlét'!V43-1 & "x" &'Jelenlét'!$Z43," ")
B20: FALSE | C20: FALSE | D20: TRUE | E20: FALSE | F20: TRUE | G20: TRUE | H20: TRUE | I20: TRUE | J20: TRUE | K20: FALSE | L20: FALSE | M20: FALSE | N20: FALSE | O20: FALSE | P20: FALSE | Q20: FALSE | R20: FALSE | S20: TRUE | T20: TRUE | U20: TRUE | V20: TRUE
A21: Szeptember | B21: =IF(COUNTIF('Jelenlét'!B44:B48,">1")=0,SUM('Számolás'!B44:B48),SUM('Számolás'!B44:B48)) -> 0 | C21: =IF(COUNTIF('Jelenlét'!C44:C48,">1")=0,SUM('Számolás'!C44:C48),SUM('Számolás'!C44:C48)) -> 3867.8095 | D21: =IF(COUNTIF('Jelenlét'!D44:D48,">1")=0,SUM('Számolás'!D44:D48),SUM('Számolás'!D44:D48)) -> 9591.0857 | E21: =IF(COUNTIF('Jelenlét'!E44:E48,">1")=0,SUM('Számolás'!E44:E48),SUM('Számolás'!E44:E48)) -> 7140.5714 | F21: =IF(COUNTIF('Jelenlét'!F44:F48,">1")=0,SUM('Számolás'!F44:F48),SUM('Számolás'!F44:F48)) -> 5723.2762 | G21: =IF(COUNTIF('Jelenlét'!G44:G48,">1")=0,SUM('Számolás'!G44:G48),SUM('Számolás'!G44:G48)) -> 13161.371 | H21: =IF(COUNTIF('Jelenlét'!H44:H48,">1")=0,SUM('Számolás'!H44:H48),SUM('Számolás'!H44:H48)) -> 5236.419 | I21: =IF(COUNTIF('Jelenlét'!I44:I48,">1")=0,SUM('Számolás'!I44:I48),SUM('Számolás'!I44:I48)) -> 9591.0857 | ... V21: =IF(COUNTIF('Jelenlét'!V44:V48,">1")=0,SUM('Számolás'!V44:V48),SUM('Számolás'!V44:V48)) -> 12923.352 | W21: =SUM(B21:V21) -> 124960
B22: =IF('Jelenlét'!B46>1,'Jelenlét'!B46-1 & "x" &'Jelenlét'!$Z46," ") | C22: =IF('Jelenlét'!C46>1,'Jelenlét'!C46-1 & "x" &'Jelenlét'!$Z46," ") | D22: =IF('Jelenlét'!D46>1,'Jelenlét'!D46-1 & "x" &'Jelenlét'!$Z46," ") | E22: =IF('Jelenlét'!E46>1,'Jelenlét'!E46-1 & "x" &'Jelenlét'!$Z46," ") -> 1x1785,14285714286 | F22: =IF('Jelenlét'!F46>1,'Jelenlét'!F46-1 & "x" &'Jelenlét'!$Z46," ") | G22: =IF('Jelenlét'!G46>1,'Jelenlét'!G46-1 & "x" &'Jelenlét'!$Z46," ") -> 1x1785,14285714286 | H22: =IF('Jelenlét'!H46>1,'Jelenlét'!H46-1 & "x" &'Jelenlét'!$Z46," ") | I22: =IF('Jelenlét'!I46>1,'Jelenlét'!I46-1 & "x" &'Jelenlét'!$Z46," ") | ... V22: =IF('Jelenlét'!V46>1,'Jelenlét'!V46-1 & "x" &'Jelenlét'!$Z46," ")
B23: =IF('Jelenlét'!B47>1,'Jelenlét'!B47-1 & "x" &'Jelenlét'!$Z47," ") | C23: =IF('Jelenlét'!C47>1,'Jelenlét'!C47-1 & "x" &'Jelenlét'!$Z47," ") | D23: =IF('Jelenlét'!D47>1,'Jelenlét'!D47-1 & "x" &'Jelenlét'!$Z47," ") | E23: =IF('Jelenlét'!E47>1,'Jelenlét'!E47-1 & "x" &'Jelenlét'!$Z47," ") -> 1x1785,14285714286 | F23: =IF('Jelenlét'!F47>1,'Jelenlét'!F47-1 & "x" &'Jelenlét'!$Z47," ") | G23: =IF('Jelenlét'!G47>1,'Jelenlét'!G47-1 & "x" &'Jelenlét'!$Z47," ") -> 1x1785,14285714286 | H23: =IF('Jelenlét'!H47>1,'Jelenlét'!H47-1 & "x" &'Jelenlét'!$Z47," ") | I23: =IF('Jelenlét'!I47>1,'Jelenlét'!I47-1 & "x" &'Jelenlét'!$Z47," ") | ... V23: =IF('Jelenlét'!V47>1,'Jelenlét'!V47-1 & "x" &'Jelenlét'!$Z47," ")
B24: =IF('Jelenlét'!B48>1,'Jelenlét'!B48-1 & "x" &'Jelenlét'!$Z48," ") | C24: =IF('Jelenlét'!C48>1,'Jelenlét'!C48-1 & "x" &'Jelenlét'!$Z48," ") | D24: =IF('Jelenlét'!D48>1,'Jelenlét'!D48-1 & "x" &'Jelenlét'!$Z48," ") | E24: =IF('Jelenlét'!E48>1,'Jelenlét'!E48-1 & "x" &'Jelenlét'!$Z48," ") | F24: =IF('Jelenlét'!F48>1,'Jelenlét'!F48-1 & "x" &'Jelenlét'!$Z48," ") | G24: =IF('Jelenlét'!G48>1,'Jelenlét'!G48-1 & "x" &'Jelenlét'!$Z48," ") | H24: =IF('Jelenlét'!H48>1,'Jelenlét'!H48-1 & "x" &'Jelenlét'!$Z48," ") | I24: =IF('Jelenlét'!I48>1,'Jelenlét'!I48-1 & "x" &'Jelenlét'!$Z48," ") | ... V24: =IF('Jelenlét'!V48>1,'Jelenlét'!V48-1 & "x" &'Jelenlét'!$Z48," ") -> 2x1666,13333333333
B25: =IF('Jelenlét'!B49>1,'Jelenlét'!B49-1 & "x" &'Jelenlét'!$Z49," ") | C25: =IF('Jelenlét'!C49>1,'Jelenlét'!C49-1 & "x" &'Jelenlét'!$Z49," ") | D25: =IF('Jelenlét'!D49>1,'Jelenlét'!D49-1 & "x" &'Jelenlét'!$Z49," ") | E25: =IF('Jelenlét'!E49>1,'Jelenlét'!E49-1 & "x" &'Jelenlét'!$Z49," ") | F25: =IF('Jelenlét'!F49>1,'Jelenlét'!F49-1 & "x" &'Jelenlét'!$Z49," ") -> 1x1780 | G25: =IF('Jelenlét'!G49>1,'Jelenlét'!G49-1 & "x" &'Jelenlét'!$Z49," ") | H25: =IF('Jelenlét'!H49>1,'Jelenlét'!H49-1 & "x" &'Jelenlét'!$Z49," ") | I25: =IF('Jelenlét'!I49>1,'Jelenlét'!I49-1 & "x" &'Jelenlét'!$Z49," ") | ... V25: =IF('Jelenlét'!V49>1,'Jelenlét'!V49-1 & "x" &'Jelenlét'!$Z49," ")
B26: FALSE | C26: FALSE | D26: TRUE | E26: TRUE | F26: TRUE | G26: TRUE | H26: TRUE | I26: TRUE | J26: TRUE | K26: FALSE | L26: FALSE | M26: FALSE | N26: FALSE | O26: FALSE | P26: FALSE | Q26: FALSE | R26: TRUE | S26: TRUE | T26: TRUE | U26: TRUE | V26: TRUE
